Workbook

Sheet тахлил
A1: table_name | B1: table_schema | C1: =B1&"."&A1 -> table_schema.table_name | D1: Аниқлик киритиш керак | E1: изох | F1: +- | H1: Мавжуд | N1: қидирув 1 | O1: қидирув 2 | P1: Итог
A2: credits | B2: education | C2: =B2&"."&A2 -> education.credits | D2: =IFERROR(VLOOKUP(A2,#REF!,1,0),VLOOKUP(C2,#REF!,1,0)) -> #REF! | E2: delete | F2: - | H2: financial_transactions | N2: =IFERROR(VLOOKUP(H2,A:A,1,0),"") -> financial_transactions | O2: =IFERROR(VLOOKUP(H2,C:C,1,0),"") | P2: =N2&O2 -> financial_transactions
A3: dtm_recommends | B3: education | C3: =B3&"."&A3 -> education.dtm_recommends | D3: =IFERROR(VLOOKUP(A3,#REF!,1,0),VLOOKUP(C3,#REF!,1,0)) -> #REF! | E3: delete | F3: - | H3: dembat_faktura | N3: =IFERROR(VLOOKUP(H3,A:A,1,0),"") -> dembat_faktura | O3: =IFERROR(VLOOKUP(H3,C:C,1,0),"") | P3: =N3&O3 -> dembat_faktura
A4: dtm_transfers | B4: education | C4: =B4&"."&A4 -> education.dtm_transfers | D4: =IFERROR(VLOOKUP(A4,#REF!,1,0),VLOOKUP(C4,#REF!,1,0)) -> #REF! | E4: delete | F4: - | N4: =IFERROR(VLOOKUP(H4,A:A,1,0),"") | O4: =IFERROR(VLOOKUP(H4,C:C,1,0),"") | P4: =N4&O4
A5: hemis_graduates | B5: education | C5: =B5&"."&A5 -> education.hemis_graduates | D5: =IFERROR(VLOOKUP(A5,#REF!,1,0),VLOOKUP(C5,#REF!,1,0)) -> #REF! | E5: delete | F5: - | N5: =IFERROR(VLOOKUP(H5,A:A,1,0),"") | O5: =IFERROR(VLOOKUP(H5,C:C,1,0),"") | P5: =N5&O5
A6: hemis_students | B6: education | C6: =B6&"."&A6 -> education.hemis_students | D6: =IFERROR(VLOOKUP(A6,#REF!,1,0),VLOOKUP(C6,#REF!,1,0)) -> #REF! | E6: delete | F6: - | H6: report_months | N6: =IFERROR(VLOOKUP(H6,A:A,1,0),"") -> report_months | O6: =IFERROR(VLOOKUP(H6,C:C,1,0),"") | P6: =N6&O6 -> report_months
A7: borders | B7: employement | C7: =B7&"."&A7 -> employement.borders | D7: =IFERROR(VLOOKUP(A7,#REF!,1,0),VLOOKUP(C7,#REF!,1,0)) -> #REF! | E7: pagran | F7: - | H7: position_vault | I7: positions_vault | N7: =IFERROR(VLOOKUP(H7,A:A,1,0),"") -> position_vault | O7: =IFERROR(VLOOKUP(H7,C:C,1,0),"") | P7: =N7&O7 -> position_vault
A8: inps | B8: employement | C8: =B8&"."&A8 -> employement.inps | D8: =IFERROR(VLOOKUP(A8,#REF!,1,0),VLOOKUP(C8,#REF!,1,0)) -> #REF! | E8: delete | F8: - | H8: vedemost | N8: =IFERROR(VLOOKUP(H8,A:A,1,0),"") -> vedemost | O8: =IFERROR(VLOOKUP(H8,C:C,1,0),"") | P8: =N8&O8 -> vedemost
A9: mymehnat | B9: employement | C9: =B9&"."&A9 -> employement.mymehnat | D9: =IFERROR(VLOOKUP(A9,#REF!,1,0),VLOOKUP(C9,#REF!,1,0)) -> #REF! | E9: delete | F9: - | N9: =IFERROR(VLOOKUP(H9,A:A,1,0),"") | O9: =IFERROR(VLOOKUP(H9,C:C,1,0),"") | P9: =N9&O9
A10: mymehnat_history | B10: employement | C10: =B10&"."&A10 -> employement.mymehnat_history | D10: =IFERROR(VLOOKUP(A10,#REF!,1,0),VLOOKUP(C10,#REF!,1,0)) -> #REF! | E10: delete | F10: - | H10: student_info | N10: =IFERROR(VLOOKUP(H10,A:A,1,0),"") -> student_info | O10: =IFERROR(VLOOKUP(H10,C:C,1,0),"") | P10: =N10&O10 -> student_info
A11: deaths | B11: minyust | C11: =B11&"."&A11 -> minyust.deaths | D11: =IFERROR(VLOOKUP(A11,#REF!,1,0),VLOOKUP(C11,#REF!,1,0)) -> #REF! | E11: ulganlar | F11: - | N11: =IFERROR(VLOOKUP(H11,A:A,1,0),"") | O11: =IFERROR(VLOOKUP(H11,C:C,1,0),"") | P11: =N11&O11
A12: authorized_funds | B12: minyust | C12: =B12&"."&A12 -> minyust.authorized_funds | D12: =IFERROR(VLOOKUP(A12,#REF!,1,0),VLOOKUP(C12,#REF!,1,0)) -> #REF! | E12: tasisci_history | F12: - | N12: =IFERROR(VLOOKUP(H12,A:A,1,0),"") | O12: =IFERROR(VLOOKUP(H12,C:C,1,0),"") | P12: =N12&O12
A13: birth_extra | B13: minyust | C13: =B13&"."&A13 -> minyust.birth_extra | D13: =IFERROR(VLOOKUP(A13,#REF!,1,0),VLOOKUP(C13,#REF!,1,0)) -> #REF! | E13: delete | F13: - | H13: education.teacher | N13: =IFERROR(VLOOKUP(H13,A:A,1,0),"") | O13: =IFERROR(VLOOKUP(H13,C:C,1,0),"") -> education.teacher | P13: =N13&O13 -> education.teacher
A14: birth_fulled | B14: minyust | C14: =B14&"."&A14 -> minyust.birth_fulled | D14: =IFERROR(VLOOKUP(A14,#REF!,1,0),VLOOKUP(C14,#REF!,1,0)) -> #REF! | E14: tugulish | F14: - | N14: =IFERROR(VLOOKUP(H14,A:A,1,0),"") | O14: =IFERROR(VLOOKUP(H14,C:C,1,0),"") | P14: =N14&O14
A15: death_extra | B15: minyust | C15: =B15&"."&A15 -> minyust.death_extra | D15: =IFERROR(VLOOKUP(A15,#REF!,1,0),VLOOKUP(C15,#REF!,1,0)) -> #REF! | E15: delete | F15: - | N15: =IFERROR(VLOOKUP(H15,A:A,1,0),"") | O15: =IFERROR(VLOOKUP(H15,C:C,1,0),"") | P15: =N15&O15
A16: founders | B16: minyust | C16: =B16&"."&A16 -> minyust.founders | D16: =IFERROR(VLOOKUP(A16,#REF!,1,0),VLOOKUP(C16,#REF!,1,0)) -> #REF! | E16: delete | F16: - | N16: =IFERROR(VLOOKUP(H16,A:A,1,0),"") | O16: =IFERROR(VLOOKUP(H16,C:C,1,0),"") | P16: =N16&O16
A17: half_birth | B17: minyust | C17: =B17&"."&A17 -> minyust.half_birth | D17: =IFERROR(VLOOKUP(A17,#REF!,1,0),VLOOKUP(C17,#REF!,1,0)) -> #REF! | E17: tugulish_davomi | F17: - | N17: =IFERROR(VLOOKUP(H17,A:A,1,0),"") | O17: =IFERROR(VLOOKUP(H17,C:C,1,0),"") | P17: =N17&O17
A18: person | B18: minyust | C18: =B18&"."&A18 -> minyust.person | D18: =IFERROR(VLOOKUP(A18,#REF!,1,0),VLOOKUP(C18,#REF!,1,0)) -> #REF! | E18: pasport | F18: - | H18: customers_jur | I18: customers_phys | N18: =IFERROR(VLOOKUP(H18,A:A,1,0),"") -> customers_jur | O18: =IFERROR(VLOOKUP(H18,C:C,1,0),"") | P18: =N18&O18 -> customers_jur
A19: person_red_passport | B19: minyust | C19: =B19&"."&A19 -> minyust.person_red_passport | D19: =IFERROR(VLOOKUP(A19,#REF!,1,0),VLOOKUP(C19,#REF!,1,0)) -> #REF! | E19: ped_pasport | F19: - | H19: gaz_elektr.meters | N19: =IFERROR(VLOOKUP(H19,A:A,1,0),"") | O19: =IFERROR(VLOOKUP(H19,C:C,1,0),"") -> gaz_elektr.meters | P19: =N19&O19 -> gaz_elektr.meters
A20: Inappsite_appusagemonitoring | B20: public | C20: =B20&"."&A20 -> public.Inappsite_appusagemonitoring | D20: =IFERROR(VLOOKUP(A20,#REF!,1,0),VLOOKUP(C20,#REF!,1,0)) -> #REF! | E20: delete | F20: - | N20: =IFERROR(VLOOKUP(H20,A:A,1,0),"") | O20: =IFERROR(VLOOKUP(H20,C:C,1,0),"") | P20: =N20&O20
A21: conflictofinterests | B21: public | C21: =B21&"."&A21 -> public.conflictofinterests | D21: =IFERROR(VLOOKUP(A21,#REF!,1,0),VLOOKUP(C21,#REF!,1,0)) -> #REF! | E21: delete | F21: - | H21: geo_eco.yer_osti_uchastka | N21: =IFERROR(VLOOKUP(H21,A:A,1,0),"") | O21: =IFERROR(VLOOKUP(H21,C:C,1,0),"") -> geo_eco.yer_osti_uchastka | P21: =N21&O21 -> geo_eco.yer_osti_uchastka
A22: e_qaror | B22: public | C22: =B22&"."&A22 -> public.e_qaror | D22: =IFERROR(VLOOKUP(A22,#REF!,1,0),VLOOKUP(C22,#REF!,1,0)) -> #REF! | E22: delete | F22: - | H22: geo_eco.qazilma_hajmi | N22: =IFERROR(VLOOKUP(H22,A:A,1,0),"") | O22: =IFERROR(VLOOKUP(H22,C:C,1,0),"") -> geo_eco.qazilma_hajmi | P22: =N22&O22 -> geo_eco.qazilma_hajmi
A23: ehf_copy1 | B23: public | C23: =B23&"."&A23 -> public.ehf_copy1 | D23: =IFERROR(VLOOKUP(A23,#REF!,1,0),VLOOKUP(C23,#REF!,1,0)) -> #REF! | E23: delete | F23: - | H23: geo_eco.yer_osti_suv | N23: =IFERROR(VLOOKUP(H23,A:A,1,0),"") | O23: =IFERROR(VLOOKUP(H23,C:C,1,0),"") -> geo_eco.yer_osti_suv | P23: =N23&O23 -> geo_eco.yer_osti_suv
A24: ehf_copy2 | B24: public | C24: =B24&"."&A24 -> public.ehf_copy2 | D24: =IFERROR(VLOOKUP(A24,#REF!,1,0),VLOOKUP(C24,#REF!,1,0)) -> #REF! | E24: delete | F24: - | H24: geo_eco.choraklik_hajm | N24: =IFERROR(VLOOKUP(H24,A:A,1,0),"") | O24: =IFERROR(VLOOKUP(H24,C:C,1,0),"") -> geo_eco.choraklik_hajm | P24: =N24&O24 -> geo_eco.choraklik_hajm
A25: faktura_2022-2023 | B25: public | C25: =B25&"."&A25 -> public.faktura_2022-2023 | D25: =IFERROR(VLOOKUP(A25,#REF!,1,0),VLOOKUP(C25,#REF!,1,0)) -> #REF! | E25: delete | F25: - | N25: =IFERROR(VLOOKUP(H25,A:A,1,0),"") | O25: =IFERROR(VLOOKUP(H25,C:C,1,0),"") | P25: =N25&O25
A26: newtable | B26: public | C26: =B26&"."&A26 -> public.newtable | D26: =IFERROR(VLOOKUP(A26,#REF!,1,0),VLOOKUP(C26,#REF!,1,0)) -> #REF! | E26: delete | F26: - | N26: =IFERROR(VLOOKUP(H26,A:A,1,0),"") | O26: =IFERROR(VLOOKUP(H26,C:C,1,0),"") | P26: =N26&O26
A27: opendata.api.eqaror | B27: public | C27: =B27&"."&A27 -> public.opendata.api.eqaror | D27: =IFERROR(VLOOKUP(A27,#REF!,1,0),VLOOKUP(C27,#REF!,1,0)) -> #REF! | E27: delete | F27: - | N27: =IFERROR(VLOOKUP(H27,A:A,1,0),"") | O27: =IFERROR(VLOOKUP(H27,C:C,1,0),"") | P27: =N27&O27
A28: opendata.api.history | B28: public | C28: =B28&"."&A28 -> public.opendata.api.history | D28: =IFERROR(VLOOKUP(A28,#REF!,1,0),VLOOKUP(C28,#REF!,1,0)) -> #REF! | E28: delete | F28: - | N28: =IFERROR(VLOOKUP(H28,A:A,1,0),"") | O28: =IFERROR(VLOOKUP(H28,C:C,1,0),"") | P28: =N28&O28
A29: opendata.api.users | B29: public | C29: =B29&"."&A29 -> public.opendata.api.users | D29: =IFERROR(VLOOKUP(A29,#REF!,1,0),VLOOKUP(C29,#REF!,1,0)) -> #REF! | E29: delete | F29: - | N29: =IFERROR(VLOOKUP(H29,A:A,1,0),"") | O29: =IFERROR(VLOOKUP(H29,C:C,1,0),"") | P29: =N29&O29
A30: opendata.region.data | B30: public | C30: =B30&"."&A30 -> public.opendata.region.data | D30: =IFERROR(VLOOKUP(A30,#REF!,1,0),VLOOKUP(C30,#REF!,1,0)) -> #REF! | E30: delete | F30: - | N30: =IFERROR(VLOOKUP(H30,A:A,1,0),"") | O30: =IFERROR(VLOOKUP(H30,C:C,1,0),"") | P30: =N30&O30
A31: opendata.region.users | B31: public | C31: =B31&"."&A31 -> public.opendata.region.users | D31: =IFERROR(VLOOKUP(A31,#REF!,1,0),VLOOKUP(C31,#REF!,1,0)) -> #REF! | E31: delete | F31: - | N31: =IFERROR(VLOOKUP(H31,A:A,1,0),"") | O31: =IFERROR(VLOOKUP(H31,C:C,1,0),"") | P31: =N31&O31
A32: paragraph | B32: public | C32: =B32&"."&A32 -> public.paragraph | D32: =IFERROR(VLOOKUP(A32,#REF!,1,0),VLOOKUP(C32,#REF!,1,0)) -> #REF! | E32: delete | F32: - | N32: =IFERROR(VLOOKUP(H32,A:A,1,0),"") | O32: =IFERROR(VLOOKUP(H32,C:C,1,0),"") | P32: =N32&O32
A33: soliq_oylik | B33: public | C33: =B33&"."&A33 -> public.soliq_oylik | D33: =IFERROR(VLOOKUP(A33,#REF!,1,0),VLOOKUP(C33,#REF!,1,0)) -> #REF! | E33: delete | F33: - | N33: =IFERROR(VLOOKUP(H33,A:A,1,0),"") | O33: =IFERROR(VLOOKUP(H33,C:C,1,0),"") | P33: =N33&O33
A34: soliq_token | B34: public | C34: =B34&"."&A34 -> public.soliq_token | D34: =IFERROR(VLOOKUP(A34,#REF!,1,0),VLOOKUP(C34,#REF!,1,0)) -> #REF! | E34: delete | F34: - | H34: qurilish.object_pudrat | N34: =IFERROR(VLOOKUP(H34,A:A,1,0),"") | O34: =IFERROR(VLOOKUP(H34,C:C,1,0),"") -> qurilish.object_pudrat | P34: =N34&O34 -> qurilish.object_pudrat
A35: tax_ehf2022 | B35: public | C35: =B35&"."&A35 -> public.tax_ehf2022 | D35: =IFERROR(VLOOKUP(A35,#REF!,1,0),VLOOKUP(C35,#REF!,1,0)) -> #REF! | E35: delete | F35: - | H35: qurilish.object_loyiha | N35: =IFERROR(VLOOKUP(H35,A:A,1,0),"") | O35: =IFERROR(VLOOKUP(H35,C:C,1,0),"") -> qurilish.object_loyiha | P35: =N35&O35 -> qurilish.object_loyiha
A36: tax_salary | B36: public | C36: =B36&"."&A36 -> public.tax_salary | D36: =IFERROR(VLOOKUP(A36,#REF!,1,0),VLOOKUP(C36,#REF!,1,0)) -> #REF! | E36: delete | F36: - | H36: qurilish.object_winner_pudrat | N36: =IFERROR(VLOOKUP(H36,A:A,1,0),"") | O36: =IFERROR(VLOOKUP(H36,C:C,1,0),"") -> qurilish.object_winner_pudrat | P36: =N36&O36 -> qurilish.object_winner_pudrat
A37: tax_shot_faktura | B37: public | C37: =B37&"."&A37 -> public.tax_shot_faktura | D37: =IFERROR(VLOOKUP(A37,#REF!,1,0),VLOOKUP(C37,#REF!,1,0)) -> #REF! | E37: delete | F37: - | H37: qurilish.object_pudrat_data | N37: =IFERROR(VLOOKUP(H37,A:A,1,0),"") | O37: =IFERROR(VLOOKUP(H37,C:C,1,0),"") -> qurilish.object_pudrat_data | P37: =N37&O37 -> qurilish.object_pudrat_data
A38: uzasbo_soliq | B38: public | C38: =B38&"."&A38 -> public.uzasbo_soliq | D38: =IFERROR(VLOOKUP(A38,#REF!,1,0),VLOOKUP(C38,#REF!,1,0)) -> #REF! | E38: delete | F38: - | H38: qurilish.object_winner_loyiha | N38: =IFERROR(VLOOKUP(H38,A:A,1,0),"") | O38: =IFERROR(VLOOKUP(H38,C:C,1,0),"") -> qurilish.object_winner_loyiha | P38: =N38&O38 -> qurilish.object_winner_loyiha
A39: sql_parts | B39: information_schema | C39: =B39&"."&A39 -> information_schema.sql_parts | D39: =IFERROR(VLOOKUP(A39,#REF!,1,0),VLOOKUP(C39,#REF!,1,0)) -> #REF! | E39: delete | F39: - | H39: agrosanoat_data | I39: ichki_ishlar_yol | J39: mehnat_vazirligi | K39: organization | L39: organization_detail | M39: sanoat_xavfsizligi | N39: =IFERROR(VLOOKUP(H39,A:A,1,0),"") -> agrosanoat_data | O39: =IFERROR(VLOOKUP(H39,C:C,1,0),"") | P39: =N39&O39 -> agrosanoat_data
A40: sql_implementation_info | B40: information_schema | C40: =B40&"."&A40 -> information_schema.sql_implementation_info | D40: =IFERROR(VLOOKUP(A40,#REF!,1,0),VLOOKUP(C40,#REF!,1,0)) -> #REF! | E40: delete | F40: - | H40: qurilish.object_loyiha_ekspertiza | N40: =IFERROR(VLOOKUP(H40,A:A,1,0),"") | O40: =IFERROR(VLOOKUP(H40,C:C,1,0),"") -> qurilish.object_loyiha_ekspertiza | P40: =N40&O40 -> qurilish.object_loyiha_ekspertiza
...

Sheet Микросервис (2025-05-24)
A1: Микросервислар орқали кунлик, ойлик ва чораклик жамланадиган маълумотлар
A3: Т/р | B3: Маълумот эгаси ҳамда унинг таркиби | C3: Маълумот олиш усули тўғрисида таклиф | D3: ҳолати | E3: Маълумот жамлаш (кунлик, ойлик, чораклик) | F3: Интеграция ҳолати (1-якунланган, 2-давом этмоқда) | G3: API | H3: Базадаги номи | J3: URL | K3: Вазирдик ва идора номи | L3: Маълумот номи | M3: Таблица номи | N3: Таблицада одам тили
B4: 1. Адлия
A5: =MAX(A$2:A4)+1 -> 1 | B5: Yaqin qarindoshlar | D5: 1 | E5: ойлик | H5: minyust.relative_person_info
A6: =MAX(A$2:A5)+1 -> 2 | B6: Bank xodimlarini yaqin qarindoshlarini yig'ish | D6: 1 | E6: ойлик | H6: minyust.relative_person_info
B7: 2. УзАСБО ДТ
A8: =MAX(A$2:A7)+1 -> 3 | B8: Uzasbo G'azna Faktura | D8: 1 | E8: кунлик | H8: uzasbo.gazna_faktura
A9: =MAX(A$2:A8)+1 -> 4 | B9: Lavozimlarni olish | D9: 1 | E9: ойлик | H9: uzasbo.position_vault | J9: http://10.190.4.11/inps/api/UzRXP/GetSqlQuery
A10: =MAX(A$2:A9)+1 -> 5 | B10: Dembat Faktura | D10: 1 | E10: ойлик | H10: uzasbo.dembat_faktura
A11: =MAX(A$2:A10)+1 -> 6 | B11: Uzasbo ish haqqi | D11: 1 | E11: сўровга асосан | H11: uzasbo.report_months | J11: http://10.190.4.11/inps/api/UzRXP/GetSqlQuery
A12: =MAX(A$2:A11)+1 -> 7 | B12: Dembat Smeta | D12: 1 | E12: кунлик | H12: uzasbo.dembat_smeta
A13: =MAX(A$2:A12)+1 -> 8 | B13: Asosiy Smeta | D13: 1 | E13: ойлик | H13: uzasbo.main_smeta
A14: =MAX(A$2:A13)+1 -> 9 | B14: Vedemost | D14: 1 | E14: сўровга асосан | H14: uzasbo.vedemost | J14: http://10.190.4.11/inps/api/UzRXP/GetSqlQuery
A15: =MAX(A$2:A14)+1 -> 10 | B15: Dembat shartnomalar | D15: 1 | E15: кунлик | H15: uzasbo.financial_transactions
A16: =MAX(A$2:A15)+1 -> 11 | B16: Organizatsiyalar | D16: 1 | E16: ойлик | H16: uzasbo.info_organizations | J16: http://10.190.4.11/inps/api/UzRXP/GetSqlQuery
A17: =MAX(A$2:A16)+1 -> 12 | B17: Position Svod | D17: 1 | E17: ойлик | H17: uzasbo.positions_vault
A18: =MAX(A$2:A17)+1 -> 13 | B18: bittadan inn yuborib Uzasbo Oylik olish | D18: 1 | E18: сўровга асосан | H18: uzasbo.report_months | J18: http://10.190.4.11/inps/api/UzRXP/GetSqlQuery
A19: =MAX(A$2:A18)+1 -> 14 | B19: Taxlil uchun Ish xaqqini tayorlash | D19: 1 | E19: сўровга асосан | H19: uzasbo.report_months_last
B20: 3. Субсидия
A21: =MAX(A$2:A20)+1 -> 15 | B21: Корхона ва ташкилотларда умумий иш ўринлари тўғрисида маълумот | D21: 1 | E21: кунлик | H21: subsidy.job_searchers_list | J21: https://10.190.2.81/api/account-chamber/job-searchers-list | K21: Камбағалликни қисқартириш ва бандлик вазирлиги | L21: Фуқароларни ишга жойлаштиришда кўмаклашиш (ишга жойлаштирилган фуқаролар) | M21: Фуқароларни ишга жойлаштиришда кўмаклашиш (жисмоний шахсларнинг меҳнат фаолияти тўғрисидаги маълумотлар) | N21: {"params": [{"type": "str", "child": false, "field": "fio", "name_cr": "F.I.SH", "name_en": "F.I.SH", "name_ru": "F.I.SH", "name_uz": "F.I.SH"}, {"type": "str", "child": false, "field": "gender", "name_cr": "Jinsi", "name_en": "Jinsi", "name_ru": "Jinsi", "name_uz": "Jinsi"}, {"type": "str", "child": false, "field": "birth_date", "name_cr": "Tug‘ilgan sanasi", "name_en": "Tug‘ilgan sanasi", "name_ru": "Tug‘ilgan sanasi", "name_uz": "Tug‘ilgan sanasi"}, {"type": "str", "child": false, "field": "passport", "name_cr": "Pasport seriya va raqami", "name_en": "Pasport seriya va raqami", "name_ru": "Pasport seriya va raqami", "name_uz": "Pasport seriya va raqami"}, {"type": "str", "child": false, "field": "tin", "name_cr": "STIR (INN)", "name_en": "STIR (INN)", "name_ru": "STIR (INN)", "name_uz": "STIR (INN)"}, {"type": "str", "child": false, "field": "pin", "name_cr": "PINFL", "name_en": "PINFL", "name_ru": "PINFL", "name_uz": "PINFL"}, {"type": "str", "child": false, "field": "phone", "name_cr": "Tel raqami", "name_en": "Tel raqami", "name_ru": "Tel raqami", "name_uz": "Tel raqami"}, {"type": "str", "child": false, "field": "application_date", "name_cr": "Ishsizlik bo‘yicha murojaat sanasi", "name_en": "Ishsizlik bo‘yicha murojaat sanasi", "name_ru": "Ishsizlik bo‘yicha murojaat sanasi", "name_uz": "Ishsizlik bo‘yicha murojaat sanasi"}, {"type": "str", "child": false, "field": "employed_date", "name_cr": "Ishga joylashtirilgan sanasi", "name_en": "Ishga joylashtirilgan sanasi", "name_ru": "Ishga joylashtirilgan sanasi", "name_uz": "Ishga joylashtirilgan sanasi"}, {"type": "str", "child": false, "field": "region_name", "name_cr": "Hudud (viloyat) nomi", "name_en": "Hudud (viloyat) nomi", "name_ru": "Hudud (viloyat) nomi", "name_uz": "Hudud (viloyat) nomi"}, {"type": "str", "child": false, "field": "region_soato", "name_cr": "Hudud (viloyat) SOATO kodi", "name_en": "Hudud (viloyat) SOATO kodi", "name_ru": "Hudud (viloyat) SOATO kodi", "name_uz": "Hudud (viloyat) SOATO kodi"}, {"type": "str", "child": false, "field": "district_name", "name_cr": "Tuman (shahar) nomi", "name_en": "Tuman (shahar) nomi", "name_ru": "Tuman (shahar) nomi", "name_uz": "Tuman (shahar) nomi"}, {"type": "str", "child": false, "field": "city_soato", "name_cr": "Tuman (shahar) SOATO kodi", "name_en": "Tuman (shahar) SOATO kodi", "name_ru": "Tuman (shahar) SOATO kodi", "name_uz": "Tuman (shahar) SOATO kodi"}, {"type": "str", "child": false, "field": "company_tin", "name_cr": "Korxona STIR", "name_en": "Korxona STIR", "name_ru": "Korxona STIR", "name_uz": "Korxona STIR"}, {"type": "str", "child": false, "field": "company_name", "name_cr": "Korxona nomi", "name_en": "Korxona nomi", "name_ru": "Korxona nomi", "name_uz": "Korxona nomi"}, {"type": "str", "child": false, "field": "salary", "name_cr": "Oylik ish haqi miqdori", "name_en": "Oylik ish haqi miqdori", "name_ru": "Oylik ish haqi miqdori", "name_uz": "Oylik ish haqi miqdori"}, {"type": "str", "child": false, "field": "contract_date", "name_cr": "Mehnat shartnomasi sanasi", "name_en": "Mehnat shartnomasi sanasi", "name_ru": "Mehnat shartnomasi sanasi", "name_uz": "Mehnat shartnomasi sanasi"}, {"type": "str", "child": false, "field": "contract_expire_date", "name_cr": "Mehnat shartnomasi amal qilish muddati", "name_en": "Mehnat shartnomasi amal qilish muddati", "name_ru": "Mehnat shartnomasi amal qilish muddati", "name_uz": "Mehnat shartnomasi amal qilish muddati"}, {"type": "str", "child": false, "field": "age", "name_cr": "Yoshi", "name_en": "Yoshi", "name_ru": "Yoshi", "name_uz": "Yoshi"}]}
A22: =MAX(A$2:A21)+1 -> 16 | B22: Ҳунарманд шогирдларга асбоб ускуна учун субсидия | D22: 1 | E22: кунлик | H22: subsidy.for_students | J22: https://10.190.2.81/api/account-chamber/master-craftsman-list/for-students | K22: Камбағалликни қисқартириш ва бандлик вазирлиги | L22: Ҳунарманд шогирдларга асбоб ускуна учун субсидия | M22: Ҳунарманд шогирдларга асбоб ускуна учун субсидия | N22: {"params": [{"type": "string", "child": false, "field": "region_name", "name_cr": "region_name", "name_en": "region_name", "name_ru": "region_name", "name_uz": "region_name"}, {"type": "string", "child": false, "field": "region_soato", "name_cr": "region_soato", "name_en": "region_soato", "name_ru": "region_soato", "name_uz": "region_soato"}, {"type": "string", "child": false, "field": "district_name", "name_cr": "district_name", "name_en": "district_name", "name_ru": "district_name", "name_uz": "district_name"}, {"type": "string", "child": false, "field": "city_soato", "name_cr": "city_soato", "name_en": "city_soato", "name_ru": "city_soato", "name_uz": "city_soato"}, {"type": "string", "child": false, "field": "bdate", "name_cr": "bdate", "name_en": "bdate", "name_ru": "bdate", "name_uz": "bdate"}, {"type": "string", "child": false, "field": "psdata", "name_cr": "psdata", "name_en": "psdata", "name_ru": "psdata", "name_uz": "psdata"}, {"type": "string", "child": false, "field": "inn", "name_cr": "inn", "name_en": "inn", "name_ru": "inn", "name_uz": "inn"}, {"type": "string", "child": false, "field": "pinfl", "name_cr": "pinfl", "name_en": "pinfl", "name_ru": "pinfl", "name_uz": "pinfl"}, {"type": "string", "child": false, "field": "sex", "name_cr": "sex", "name_en": "sex", "name_ru": "sex", "name_uz": "sex"}, {"type": "string", "child": false, "field": "full_name", "name_cr": "full_name", "name_en": "full_name", "name_ru": "full_name", "name_uz": "full_name"}, {"type": "string", "child": false, "field": "subsidy_amount", "name_cr": "subsidy_amount", "name_en": "subsidy_amount", "name_ru": "subsidy_amount", "name_uz": "subsidy_amount"}, {"type": "string", "child": false, "field": "subsidy_date", "name_cr": "subsidy_date", "name_en": "subsidy_date", "name_ru": "subsidy_date", "name_uz": "subsidy_date"}, {"type": "string", "child": false, "field": "subsidy_name", "name_cr": "subsidy_name", "name_en": "subsidy_name", "name_ru": "subsidy_name", "name_uz": "subsidy_name"}]}
A23: =MAX(A$2:A22)+1 -> 17 | B23: Ҳунарманд уюшмасига аъзолик бадалини қоплаш учун субсидия | D23: 1 | E23: кунлик | H23: subsidy.for_membership_fee | J23: https://10.190.2.81/api/account-chamber/master-craftsman-list/for-membership-fee | K23: Камбағалликни қисқартириш ва бандлик вазирлиги | L23: Ҳунарманд уюшмасига аъзолик бадалини қоплаш учун субсидия | M23: Ҳунарманд уюшмасига аъзолик бадалини қоплаш учун субсидия | N23: {"params": [{"type": "string", "child": false, "field": "region_name", "name_cr": "region_name", "name_en": "region_name", "name_ru": "region_name", "name_uz": "region_name"}, {"type": "string", "child": false, "field": "region_soato", "name_cr": "region_soato", "name_en": "region_soato", "name_ru": "region_soato", "name_uz": "region_soato"}, {"type": "string", "child": false, "field": "district_name", "name_cr": "district_name", "name_en": "district_name", "name_ru": "district_name", "name_uz": "district_name"}, {"type": "string", "child": false, "field": "city_soato", "name_cr": "city_soato", "name_en": "city_soato", "name_ru": "city_soato", "name_uz": "city_soato"}, {"type": "string", "child": false, "field": "bdate", "name_cr": "bdate", "name_en": "bdate", "name_ru": "bdate", "name_uz": "bdate"}, {"type": "string", "child": false, "field": "psdata", "name_cr": "psdata", "name_en": "psdata", "name_ru": "psdata", "name_uz": "psdata"}, {"type": "string", "child": false, "field": "inn", "name_cr": "inn", "name_en": "inn", "name_ru": "inn", "name_uz": "inn"}, {"type": "string", "child": false, "field": "pinfl", "name_cr": "pinfl", "name_en": "pinfl", "name_ru": "pinfl", "name_uz": "pinfl"}, {"type": "string", "child": false, "field": "sex", "name_cr": "sex", "name_en": "sex", "name_ru": "sex", "name_uz": "sex"}, {"type": "string", "child": false, "field": "full_name", "name_cr": "full_name", "name_en": "full_name", "name_ru": "full_name", "name_uz": "full_name"}, {"type": "string", "child": false, "field": "subsidy_amount", "name_cr": "subsidy_amount", "name_en": "subsidy_amount", "name_ru": "subsidy_amount", "name_uz": "subsidy_amount"}, {"type": "string", "child": false, "field": "subsidy_date", "name_cr": "subsidy_date", "name_en": "subsidy_date", "name_ru": "subsidy_date", "name_uz": "subsidy_date"}, {"type": "string", "child": false, "field": "subsidy_name", "name_cr": "subsidy_name", "name_en": "subsidy_name", "name_ru": "subsidy_name", "name_uz": "subsidy_name"}]}
A24: =MAX(A$2:A23)+1 -> 18 | B24: Касбга ўқитиш хизматидан фойдаланган жисмоний шахслар тўғрисидаги маълумотлар | D24: 1 | E24: кунлик | H24: subsidy.kasbga_yun_fuqaro | J24: https://10.190.2.81/api/account-chamber/retraining-list | K24: Камбағалликни қисқартириш ва бандлик вазирлиги | L24: Касбга ўқитиш хизматидан фойдаланган жисмоний шахслар тўғрисидаги маълумотлар | M24: Касбга ўқитиш хизматидан фойдаланган жисмоний шахслар тўғрисидаги маълумотлар | N24: {"params": [{"type": "string", "child": false, "field": "parent_structure", "name_cr": "parent_structure", "name_en": "parent_structure", "name_ru": "parent_structure", "name_uz": "parent_structure"}, {"type": "string", "child": false, "field": "structure", "name_cr": "structure", "name_en": "structure", "name_ru": "structure", "name_uz": "structure"}, {"type": "string", "child": false, "field": "soato", "name_cr": "soato", "name_en": "soato", "name_ru": "soato", "name_uz": "soato"}, {"type": "string", "child": false, "field": "sector", "name_cr": "sector", "name_en": "sector", "name_ru": "sector", "name_uz": "sector"}, {"type": "string", "child": false, "field": "makhalla", "name_cr": "makhalla", "name_en": "makhalla", "name_ru": "makhalla", "name_uz": "makhalla"}, {"type": "string", "child": false, "field": "date_from", "name_cr": "date_from", "name_en": "date_from", "name_ru": "date_from", "name_uz": "date_from"}, {"type": "string", "child": false, "field": "date_to", "name_cr": "date_to", "name_en": "date_to", "name_ru": "date_to", "name_uz": "date_to"}, {"type": "string", "child": false, "field": "full_name", "name_cr": "full_name", "name_en": "full_name", "name_ru": "full_name", "name_uz": "full_name"}, {"type": "string", "child": false, "field": "type", "name_cr": "type", "name_en": "type", "name_ru": "type", "name_uz": "type"}, {"type": "string", "child": false, "field": "service_result", "name_cr": "service_result", "name_en": "service_result", "name_ru": "service_result", "name_uz": "service_result"}, {"type": "string", "child": false, "field": "birth_date", "name_cr": "birth_date", "name_en": "birth_date", "name_ru": "birth_date", "name_uz": "birth_date"}, {"type": "string", "child": false, "field": "passport", "name_cr": "passport", "name_en": "passport", "name_ru": "passport", "name_uz": "passport"}, {"type": "string", "child": false, "field": "pin", "name_cr": "pin", "name_en": "pin", "name_ru": "pin", "name_uz": "pin"}, {"type": "string", "child": false, "field": "gender", "name_cr": "gender", "name_en": "gender", "name_ru": "gender", "name_uz": "gender"}, {"type": "string", "child": false, "field": "phone", "name_cr": "phone", "name_en": "phone", "name_ru": "phone", "name_uz": "phone"}, {"type": "string", "child": false, "field": "scholarship", "name_cr": "scholarship", "name_en": "scholarship", "name_ru": "scholarship", "name_uz": "scholarship"}, {"type": "string", "child": false, "field": "service_date", "name_cr": "service_date", "name_en": "service_date", "name_ru": "service_date", "name_uz": "service_date"}, {"type": "string", "child": false, "field": "institution_name", "name_cr": "institution_name", "name_en": "institution_name", "name_ru": "institution_name", "name_uz": "institution_name"}, {"type": "string", "child": false, "field": "institution_tin", "name_cr": "institution_tin", "name_en": "institution_tin", "name_ru": "institution_tin", "name_uz": "institution_tin"}, {"type": "string", "child": false, "field": "institution_address", "name_cr": "institution_address", "name_en": "institution_address", "name_ru": "institution_address", "name_uz": "institution_address"}, {"type": "string", "child": false, "field": "direction", "name_cr": "direction", "name_en": "direction", "name_ru": "direction", "name_uz": "direction"}, {"type": "string", "child": false, "field": "period", "name_cr": "period", "name_en": "period", "name_ru": "period", "name_uz": "period"}]}
A25: =MAX(A$2:A24)+1 -> 19 | B25: Jamoat ishlarida band bo‘lganlar to‘g‘risidagi ma’lumotlar. | D25: 1 | E25: кунлик | H25: subsidy.public_workers_list | J25: https://10.190.2.81/api/account-chamber/public-workers-list | K25: Камбағалликни қисқартириш ва бандлик вазирлиги | L25: Жамоат ишларида банд бўлганлар тўғрисидаги маълумотлар | M25: Ҳақ тўланадиган жамоат ишларига жалб қилиш (жамоат ишларида банд бўлганлар тўғрисидаги маълумотлар) | N25: {"params": [{"type": "string", "child": false, "field": "ID", "name_cr": "ID", "name_en": "ID", "name_ru": "ID", "name_uz": "ID"}, {"type": "string", "child": false, "field": "region_name", "name_cr": "region_name", "name_en": "region_name", "name_ru": "region_name", "name_uz": "region_name"}, {"type": "string", "child": false, "field": "region_soato", "name_cr": "region_soato", "name_en": "region_soato", "name_ru": "region_soato", "name_uz": "region_soato"}, {"type": "string", "child": false, "field": "district_name", "name_cr": "district_name", "name_en": "district_name", "name_ru": "district_name", "name_uz": "district_name"}, {"type": "string", "child": false, "field": "city_soato", "name_cr": "city_soato", "name_en": "city_soato", "name_ru": "city_soato", "name_uz": "city_soato"}, {"type": "string", "child": false, "field": "company_tin", "name_cr": "company_tin", "name_en": "company_tin", "name_ru": "company_tin", "name_uz": "company_tin"}, {"type": "string", "child": false, "field": "company_name", "name_cr": "company_name", "name_en": "company_name", "name_ru": "company_name", "name_uz": "company_name"}, {"type": "string", "child": false, "field": "passport", "name_cr": "passport", "name_en": "passport", "name_ru": "passport", "name_uz": "passport"}, {"type": "string", "child": false, "field": "tin", "name_cr": "tin", "name_en": "tin", "name_ru": "tin", "name_uz": "tin"}, {"type": "string", "child": false, "field": "pin", "name_cr": "pin", "name_en": "pin", "name_ru": "pin", "name_uz": "pin"}, {"type": "string", "child": false, "field": "phone", "name_cr": "phone", "name_en": "phone", "name_ru": "phone", "name_uz": "phone"}, {"type": "string", "child": false, "field": "gender", "name_cr": "gender", "name_en": "gender", "name_ru": "gender", "name_uz": "gender"}, {"type": "string", "child": false, "field": "birth_date", "name_cr": "birth_date", "name_en": "birth_date", "name_ru": "birth_date", "name_uz": "birth_date"}, {"type": "string", "child": false, "field": "salary", "name_cr": "salary", "name_en": "salary", "name_ru": "salary", "name_uz": "salary"}, {"type": "string", "child": false, "field": "start_date", "name_cr": "start_date", "name_en": "start_date", "name_ru": "start_date", "name_uz": "start_date"}, {"type": "string", "child": false, "field": "end_date", "name_cr": "end_date", "name_en": "end_date", "name_ru": "end_date", "name_uz": "end_date"}, {"type": "string", "child": false, "field": "attended_sdate", "name_cr": "attended_sdate", "name_en": "attended_sdate", "name_ru": "attended_sdate", "name_uz": "attended_sdate"}, {"type": "string", "child": false, "field": "fullname", "name_cr": "fullname", "name_en": "fullname", "name_ru": "fullname", "name_uz": "fullname"}, {"type": "string", "child": false, "field": "company_type", "name_cr": "company_type", "name_en": "company_type", "name_ru": "company_type", "name_uz": "company_type"}, {"type": "string", "child": false, "field": "activity", "name_cr": "activity", "name_en": "activity", "name_ru": "activity", "name_uz": "activity"}, {"type": "string", "child": false, "field": "attended_edate", "name_cr": "attended_edate", "name_en": "attended_edate", "name_ru": "attended_edate", "name_uz": "attended_edate"}, {"type": "string", "child": false, "field": "age", "name_cr": "age", "name_en": "age", "name_ru": "age", "name_uz": "age"}]}
A26: =MAX(A$2:A25)+1 -> 20 | B26: Ishsizlik nafaqasini olayotgan fuqarolar to‘g‘risidagi ma’lumotlar. | D26: 1 | E26: кунлик | H26: subsidy.unemployment_list | J26: https://10.190.2.81/api/account-chamber/unemployment-list | K26: Камбағалликни қисқартириш ва бандлик вазирлиги | L26: Ишсизлик нафақасини олаётган фуқаролар тўғрисидаги маълумотлар | M26: Ишсизлик нафақасини олаётган фуқаролар тўғрисидаги маълумотлар | N26: {"params": [{"type": "str", "child": false, "field": "birth_date", "name_cr": "Tug‘ilgan sanasi", "name_en": "Tug‘ilgan sanasi", "name_ru": "Tug‘ilgan sanasi", "name_uz": "Tug‘ilgan sanasi"}, {"type": "str", "child": false, "field": "continued_date", "name_cr": "Davom ettirilgan sanasi", "name_en": "Davom ettirilgan sanasi", "name_ru": "Davom ettirilgan sanasi", "name_uz": "Davom ettirilgan sanasi"}, {"type": "str", "child": false, "field": "date_from", "name_cr": "Nafaqa muddati boshlanish sanasi (dan)", "name_en": "Nafaqa muddati boshlanish sanasi (dan)", "name_ru": "Nafaqa muddati boshlanish sanasi (dan)", "name_uz": "Nafaqa muddati boshlanish sanasi (dan)"}, {"type": "str", "child": false, "field": "date_to", "name_cr": "Nafaqa muddati tugash sanasi (gacha)", "name_en": "Nafaqa muddati tugash sanasi (gacha)", "name_ru": "Nafaqa muddati tugash sanasi (gacha)", "name_uz": "Nafaqa muddati tugash sanasi (gacha)"}, {"type": "str", "child": false, "field": "full_name", "name_cr": "F.I.O", "name_en": "F.I.O", "name_ru": "F.I.O", "name_uz": "F.I.O"}, {"type": "str", "child": false, "field": "gender", "name_cr": "Jinsi", "name_en": "Jinsi", "name_ru": "Jinsi", "name_uz": "Jinsi"}, {"type": "str", "child": false, "field": "makhalla", "name_cr": "Mahalla nomi", "name_en": "Mahalla nomi", "name_ru": "Mahalla nomi", "name_uz": "Mahalla nomi"}, {"type": "str", "child": false, "field": "parent_structure", "name_cr": "Hudud", "name_en": "Hudud", "name_ru": "Hudud", "name_uz": "Hudud"}, {"type": "str", "child": false, "field": "parent_structure", "name_cr": "Hudud", "name_en": "Hudud", "name_ru": "Hudud", "name_uz": "Hudud"}, {"type": "str", "child": false, "field": "passport", "name_cr": "Pasport seriya va raqami", "name_en": "Pasport seriya va raqami", "name_ru": "Pasport seriya va raqami", "name_uz": "Pasport seriya va raqami"}, {"type": "str", "child": false, "field": "paused_date", "name_cr": "Vaqtincha to‘xtatilgan sana", "name_en": "Vaqtincha to‘xtatilgan sana", "name_ru": "Vaqtincha to‘xtatilgan sana", "name_uz": "Vaqtincha to‘xtatilgan sana"}, {"type": "str", "child": false, "field": "paused_reason", "name_cr": "Vaqtincha to‘xtatish sababi", "name_en": "Vaqtincha to‘xtatish sababi", "name_ru": "Vaqtincha to‘xtatish sababi", "name_uz": "Vaqtincha to‘xtatish sababi"}, {"type": "str", "child": false, "field": "payment_summ", "name_cr": "Nafaqa miqdori", "name_en": "Nafaqa miqdori", "name_ru": "Nafaqa miqdori", "name_uz": "Nafaqa miqdori"}, {"type": "str", "child": false, "field": "phone", "name_cr": "Telefon raqami", "name_en": "Telefon raqami", "name_ru": "Telefon raqami", "name_uz": "Telefon raqami"}, {"type": "str", "child": false, "field": "pin", "name_cr": "JSHSHIR", "name_en": "JSHSHIR", "name_ru": "JSHSHIR", "name_uz": "JSHSHIR"}, {"type": "str", "child": false, "field": "sector", "name_cr": "Tuman sektor raqami", "name_en": "Tuman sektor raqami", "name_ru": "Tuman sektor raqami", "name_uz": "Tuman sektor raqami"}, {"type": "str", "child": false, "field": "service_date", "name_cr": "Xizmat yaratilgan (ko‘rsatilgan) sana", "name_en": "Xizmat yaratilgan (ko‘rsatilgan) sana", "name_ru": "Xizmat yaratilgan (ko‘rsatilgan) sana", "name_uz": "Xizmat yaratilgan (ko‘rsatilgan) sana"}, {"type": "str", "child": false, "field": "service_result", "name_cr": "Xizmat holati (hozirgi vaqtda)", "name_en": "Xizmat holati (hozirgi vaqtda)", "name_ru": "Xizmat holati (hozirgi vaqtda)", "name_uz": "Xizmat holati (hozirgi vaqtda)"}, {"type": "str", "child": false, "field": "soato", "name_cr": "Tuman (shahar) SOATO kodi", "name_en": "Tuman (shahar) SOATO kodi", "name_ru": "Tuman (shahar) SOATO kodi", "name_uz": "Tuman (shahar) SOATO kodi"}, {"type": "str", "child": false, "field": "stopped_reason", "name_cr": "Tugatilish sababi", "name_en": "Tugatilish sababi", "name_ru": "Tugatilish sababi", "name_uz": "Tugatilish sababi"}, {"type": "str", "child": false, "field": "structure", "name_cr": "Tuman (shahar)", "name_en": "Tuman (shahar)", "name_ru": "Tuman (shahar)", "name_uz": "Tuman (shahar)"}]}
A27: =MAX(A$2:A26)+1 -> 21 | B27: Tijorat maqsadida subsidiya olgan fuqarolar ma’lumotlari. | D27: 1 | E27: кунлик | H27: subsidy.phys_subsidies_list | J27: https://10.190.2.81/api/account-chamber/phys-subsidies-list | K27: Камбағалликни қисқартириш ва бандлик вазирлиги | L27: Субсидия олган фуқаролар тўғрисидаги маълумотлар | M27: Субсидия олган фуқаролар тўғрисидаги маълумотлар | N27: {"params": [{"type": "str", "child": false, "field": "region_name", "name_cr": "Hudud (viloyat) nomi", "name_en": "Hudud (viloyat) nomi", "name_ru": "Hudud (viloyat) nomi", "name_uz": "Hudud (viloyat) nomi"}, {"type": "str", "child": false, "field": "region_soato", "name_cr": "Hudud (viloyat) SOATO kodi", "name_en": "Hudud (viloyat) SOATO kodi", "name_ru": "Hudud (viloyat) SOATO kodi", "name_uz": "Hudud (viloyat) SOATO kodi"}, {"type": "str", "child": false, "field": "district_name", "name_cr": "Tuman (shahar) nomi", "name_en": "Tuman (shahar) nomi", "name_ru": "Tuman (shahar) nomi", "name_uz": "Tuman (shahar) nomi"}, {"type": "str", "child": false, "field": "city_soato", "name_cr": "Tuman (shahar) SOATO kodi", "name_en": "Tuman (shahar) SOATO kodi", "name_ru": "Tuman (shahar) SOATO kodi", "name_uz": "Tuman (shahar) SOATO kodi"}, {"type": "str", "child": false, "field": "bdate", "name_cr": "Tug'ilgan sanasi", "name_en": "Tug'ilgan sanasi", "name_ru": "Tug'ilgan sanasi", "name_uz": "Tug'ilgan sanasi"}, {"type": "str", "child": false, "field": "inn", "name_cr": "INN", "name_en": "INN", "name_ru": "INN", "name_uz": "INN"}, {"type": "str", "child": false, "field": "pinfl", "name_cr": "JShShIR", "name_en": "JShShIR", "name_ru": "JShShIR", "name_uz": "JShShIR"}, {"type": "str", "child": false, "field": "sex", "name_cr": "Jinsi (1-erkak 2-ayol)", "name_en": "Jinsi (1-erkak 2-ayol)", "name_ru": "Jinsi (1-erkak 2-ayol)", "name_uz": "Jinsi (1-erkak 2-ayol)"}, {"type": "str", "child": false, "field": "fname", "name_cr": "Familiya", "name_en": "Familiya", "name_ru": "Familiya", "name_uz": "Familiya"}, {"type": "str", "child": false, "field": "lname", "name_cr": "Ism", "name_en": "Ism", "name_ru": "Ism", "name_uz": "Ism"}, {"type": "str", "child": false, "field": "mname", "name_cr": "Sharifi", "name_en": "Sharifi", "name_ru": "Sharifi", "name_uz": "Sharifi"}, {"type": "str", "child": false, "field": "psdata", "name_cr": "Passport raqami", "name_en": "Passport raqami", "name_ru": "Passport raqami", "name_uz": "Passport raqami"}, {"type": "str", "child": false, "field": "subsidiya_name", "name_cr": "Subsidiya turi", "name_en": "Subsidiya turi", "name_ru": "Subsidiya turi", "name_uz": "Subsidiya turi"}, {"type": "str", "child": false, "field": "subsidiya_date", "name_cr": "Subsidiya ajratilgan sana", "name_en": "Subsidiya ajratilgan sana", "name_ru": "Subsidiya ajratilgan sana", "name_uz": "Subsidiya ajratilgan sana"}, {"type": "str", "child": false, "field": "subsidiya_summa", "name_cr": "Ajratilgan summa miqdori", "name_en": "Ajratilgan summa miqdori", "name_ru": "Ajratilgan summa miqdori", "name_uz": "Ajratilgan summa miqdori"}]}
A28: =MAX(A$2:A27)+1 -> 22 | B28: Tijorat maqsadida subsidiya olgan tashkilot ma’lumotlari. | D28: 1 | E28: кунлик | H28: subsidy.yur_subsidies_list | J28: https://10.190.2.81/api/account-chamber/yur-subsidies-list | K28: Камбағалликни қисқартириш ва бандлик вазирлиги | L28: Субсидия олган ташкилот тўғрисидаги маълумотлар | M28: Субсидия олган ташкилот тўғрисидаги маълумотлар | N28: {"params": [{"type": "str", "child": false, "field": "region_name", "name_cr": "Hudud (viloyat) nomi", "name_en": "Hudud (viloyat) nomi", "name_ru": "Hudud (viloyat) nomi", "name_uz": "Hudud (viloyat) nomi"}, {"type": "str", "child": false, "field": "region_soato", "name_cr": "Hudud (viloyat) SOATO kodi", "name_en": "Hudud (viloyat) SOATO kodi", "name_ru": "Hudud (viloyat) SOATO kodi", "name_uz": "Hudud (viloyat) SOATO kodi"}, {"type": "str", "child": false, "field": "district_name", "name_cr": "Tuman (shahar) nomi", "name_en": "Tuman (shahar) nomi", "name_ru": "Tuman (shahar) nomi", "name_uz": "Tuman (shahar) nomi"}, {"type": "str", "child": false, "field": "city_soato", "name_cr": "Tuman (shahar) SOATO kodi", "name_en": "Tuman (shahar) SOATO kodi", "name_ru": "Tuman (shahar) SOATO kodi", "name_uz": "Tuman (shahar) SOATO kodi"}, {"type": "str", "child": false, "field": "subsidy_date", "name_cr": "Subsidiya ajratilgan sana", "name_en": "Subsidiya ajratilgan sana", "name_ru": "Subsidiya ajratilgan sana", "name_uz": "Subsidiya ajratilgan sana"}, {"type": "str", "child": false, "field": "company_tin", "name_cr": "Korxona STIR", "name_en": "Korxona STIR", "name_ru": "Korxona STIR", "name_uz": "Korxona STIR"}, {"type": "str", "child": false, "field": "company_name", "name_cr": "Korxona nomi", "name_en": "Korxona nomi", "name_ru": "Korxona nomi", "name_uz": "Korxona nomi"}, {"type": "str", "child": false, "field": "subsidy_name", "name_cr": "Subsidiya turi", "name_en": "Subsidiya turi", "name_ru": "Subsidiya turi", "name_uz": "Subsidiya turi"}, {"type": "str", "child": false, "field": "subsidy_amount", "name_cr": "Ajratilgan subsidiya miqdori", "name_en": "Ajratilgan subsidiya miqdori", "name_ru": "Ajratilgan subsidiya miqdori", "name_uz": "Ajratilgan subsidiya miqdori"}]}
A29: =MAX(A$2:A28)+1 -> 23 | B29: Ҳунармандларга шогирд тайёрлаш учун субсидия | D29: 1 | E29: кунлик | H29: subsidy.for_student_training | J29: https://10.190.2.81/api/account-chamber/master-craftsman-list/for-student-training | K29: Камбағалликни қисқартириш ва бандлик вазирлиги | L29: Ҳунармандларга шогирд тайёрлаш учун субсидия | M29: Ҳунармандларга шогирд тайёрлаш учун субсидия | N29: {"params": [{"type": "string", "child": false, "field": "region_name", "name_cr": "region_name", "name_en": "region_name", "name_ru": "region_name", "name_uz": "region_name"}, {"type": "string", "child": false, "field": "region_soato", "name_cr": "region_soato", "name_en": "region_soato", "name_ru": "region_soato", "name_uz": "region_soato"}, {"type": "string", "child": false, "field": "district_name", "name_cr": "district_name", "name_en": "district_name", "name_ru": "district_name", "name_uz": "district_name"}, {"type": "string", "child": false, "field": "city_soato", "name_cr": "city_soato", "name_en": "city_soato", "name_ru": "city_soato", "name_uz": "city_soato"}, {"type": "string", "child": false, "field": "bdate", "name_cr": "bdate", "name_en": "bdate", "name_ru": "bdate", "name_uz": "bdate"}, {"type": "string", "child": false, "field": "psdata", "name_cr": "psdata", "name_en": "psdata", "name_ru": "psdata", "name_uz": "psdata"}, {"type": "string", "child": false, "field": "inn", "name_cr": "inn", "name_en": "inn", "name_ru": "inn", "name_uz": "inn"}, {"type": "string", "child": false, "field": "pinfl", "name_cr": "pinfl", "name_en": "pinfl", "name_ru": "pinfl", "name_uz": "pinfl"}, {"type": "string", "child": false, "field": "sex", "name_cr": "sex", "name_en": "sex", "name_ru": "sex", "name_uz": "sex"}, {"type": "string", "child": false, "field": "full_name", "name_cr": "full_name", "name_en": "full_name", "name_ru": "full_name", "name_uz": "full_name"}, {"type": "string", "child": false, "field": "subsidy_amount", "name_cr": "subsidy_amount", "name_en": "subsidy_amount", "name_ru": "subsidy_amount", "name_uz": "subsidy_amount"}, {"type": "string", "child": false, "field": "subsidy_date", "name_cr": "subsidy_date", "name_en": "subsidy_date", "name_ru": "subsidy_date", "name_uz": "subsidy_date"}, {"type": "string", "child": false, "field": "subsidy_name", "name_cr": "subsidy_name", "name_en": "subsidy_name", "name_ru": "subsidy_name", "name_uz": "subsidy_name"}]}
A30: =MAX(A$2:A29)+1 -> 24 | B30: Ҳунармандларга интернет сайтини яратиш учун субсидия | D30: 1 | E30: кунлик | H30: subsidy.for_web_sites | J30: https://10.190.2.81/api/account-chamber/master-craftsman-list/for-web-sites | K30: Камбағалликни қисқартириш ва бандлик вазирлиги | L30: Ҳунармандларга интернет сайтини яратиш учун субсидия | M30: Ҳунармандларга интернет сайтини яратиш учун субсидия | N30: {"params": [{"type": "string", "child": false, "field": "region_name", "name_cr": "region_name", "name_en": "region_name", "name_ru": "region_name", "name_uz": "region_name"}, {"type": "string", "child": false, "field": "region_soato", "name_cr": "region_soato", "name_en": "region_soato", "name_ru": "region_soato", "name_uz": "region_soato"}, {"type": "string", "child": false, "field": "district_name", "name_cr": "district_name", "name_en": "district_name", "name_ru": "district_name", "name_uz": "district_name"}, {"type": "string", "child": false, "field": "city_soato", "name_cr": "city_soato", "name_en": "city_soato", "name_ru": "city_soato", "name_uz": "city_soato"}, {"type": "string", "child": false, "field": "bdate", "name_cr": "bdate", "name_en": "bdate", "name_ru": "bdate", "name_uz": "bdate"}, {"type": "string", "child": false, "field": "psdata", "name_cr": "psdata", "name_en": "psdata", "name_ru": "psdata", "name_uz": "psdata"}, {"type": "string", "child": false, "field": "inn", "name_cr": "inn", "name_en": "inn", "name_ru": "inn", "name_uz": "inn"}, {"type": "string", "child": false, "field": "pinfl", "name_cr": "pinfl", "name_en": "pinfl", "name_ru": "pinfl", "name_uz": "pinfl"}, {"type": "string", "child": false, "field": "sex", "name_cr": "sex", "name_en": "sex", "name_ru": "sex", "name_uz": "sex"}, {"type": "string", "child": false, "field": "full_name", "name_cr": "full_name", "name_en": "full_name", "name_ru": "full_name", "name_uz": "full_name"}, {"type": "string", "child": false, "field": "subsidy_amount", "name_cr": "subsidy_amount", "name_en": "subsidy_amount", "name_ru": "subsidy_amount", "name_uz": "subsidy_amount"}, {"type": "string", "child": false, "field": "subsidy_date", "name_cr": "subsidy_date", "name_en": "subsidy_date", "name_ru": "subsidy_date", "name_uz": "subsidy_date"}, {"type": "string", "child": false, "field": "subsidy_name", "name_cr": "subsidy_name", "name_en": "subsidy_name", "name_ru": "subsidy_name", "name_uz": "subsidy_name"}]}
A31: =MAX(A$2:A30)+1 -> 25 | B31: Ишлаб чиқариш бирлашмаси (кооператив) аъзолигига олинган ҳар бир аъзо учун субсидия олиш | D31: 1 | E31: кунлик | H31: subsidy.coop_subsidies | J31: https://10.190.2.81/api/account-chamber/coop-subsidies | K31: Камбағалликни қисқартириш ва бандлик вазирлиги | L31: Ишлаб чиқариш бирлашмаси (кооператив) аъзолигига олинган ҳар бир аъзо учун субсидия олиш | M31: Ишлаб чиқариш бирлашмаси (кооператив) аъзолигига олинган ҳар бир аъзо учун субсидия олиш | N31: {"params": [{"type": "string", "child": false, "field": "region_name", "name_cr": "region_name", "name_en": "region_name", "name_ru": "region_name", "name_uz": "region_name"}, {"type": "string", "child": false, "field": "region_soato", "name_cr": "region_soato", "name_en": "region_soato", "name_ru": "region_soato", "name_uz": "region_soato"}, {"type": "string", "child": false, "field": "district_name", "name_cr": "district_name", "name_en": "district_name", "name_ru": "district_name", "name_uz": "district_name"}, {"type": "string", "child": false, "field": "city_soato", "name_cr": "city_soato", "name_en": "city_soato", "name_ru": "city_soato", "name_uz": "city_soato"}, {"type": "string", "child": false, "field": "subsidy_date", "name_cr": "subsidy_date", "name_en": "subsidy_date", "name_ru": "subsidy_date", "name_uz": "subsidy_date"}, {"type": "string", "child": false, "field": "company_tin", "name_cr": "company_tin", "name_en": "company_tin", "name_ru": "company_tin", "name_uz": "company_tin"}, {"type": "string", "child": false, "field": "company_name", "name_cr": "company_name", "name_en": "company_name", "name_ru": "company_name", "name_uz": "company_name"}, {"type": "string", "child": false, "field": "subsidy_name", "name_cr": "subsidy_name", "name_en": "subsidy_name", "name_ru": "subsidy_name", "name_uz": "subsidy_name"}, {"type": "string", "child": false, "field": "subsidy_amount", "name_cr": "subsidy_amount", "name_en": "subsidy_amount", "name_ru": "subsidy_amount", "name_uz": "subsidy_amount"}]}
A32: =MAX(A$2:A31)+1 -> 26 | B32: Эскпортни рағбатлантириш агентлиги Экспортчи корхоналар учун ажратилган субсидиялар тўғрисидаги маъл | D32: 1 | E32: ойлик | H32: subsidy.credits | J32: https://apiapply.epauzb.uz/api/v1/integration/requests/credit | K32: Камбағалликни қисқартириш ва бандлик вазирлиги | L32: Экспортни рағбатлантириш агентлиги томонидан тижорат банкларига тақдим этилган молиявий ресурсларнинг ажратилиши бўйича маълумотлар | M32: Экспортни рағбатлантириш агентлиги томонидан тижорат банкларига тақдим этилган молиявий ресурсларнинг ажратилиши бўйича маълумотлар | N32: {"params": [{"type": "string", "child": false, "field": "application_id", "name_cr": "application_id", "name_en": "application_id", "name_ru": "application_id", "name_uz": "application_id"}, {"type": "string", "child": false, "field": "submission_date", "name_cr": "submission_date", "name_en": "submission_date", "name_ru": "submission_date", "name_uz": "submission_date"}, {"type": "string", "child": false, "field": "commission_date", "name_cr": "commission_date", "name_en": "commission_date", "name_ru": "commission_date", "name_uz": "commission_date"}, {"type": "string", "child": false, "field": "company_name", "name_cr": "company_name", "name_en": "company_name", "name_ru": "company_name", "name_uz": "company_name"}, {"type": "string", "child": false, "field": "inn", "name_cr": "inn", "name_en": "inn", "name_ru": "inn", "name_uz": "inn"}, {"type": "string", "child": false, "field": "region", "name_cr": "region", "name_en": "region", "name_ru": "region", "name_uz": "region"}, {"type": "string", "child": false, "field": "district", "name_cr": "district", "name_en": "district", "name_ru": "district", "name_uz": "district"}, {"type": "string", "child": false, "field": "bank_name", "name_cr": "bank_name", "name_en": "bank_name", "name_ru": "bank_name", "name_uz": "bank_name"}, {"type": "string", "child": false, "field": "trading_type_name", "name_cr": "trading_type_name", "name_en": "trading_type_name", "name_ru": "trading_type_name", "name_uz": "trading_type_name"}, {"type": "string", "child": false, "field": "credit_point", "name_cr": "credit_point", "name_en": "credit_point", "name_ru": "credit_point", "name_uz": "credit_point"}, {"type": "string", "child": false, "field": "country_name", "name_cr": "country_name", "name_en": "country_name", "name_ru": "country_name", "name_uz": "country_name"}, {"type": "string", "child": false, "field": "trade_production_type", "name_cr": "trade_production_type", "name_en": "trade_production_type", "name_ru": "trade_production_type", "name_uz": "trade_production_type"}, {"type": "string", "child": false, "field": "credit_resource", "name_cr": "credit_resource", "name_en": "credit_resource", "name_ru": "credit_resource", "name_uz": "credit_resource"}, {"type": "string", "child": false, "field": "credit_sum", "name_cr": "credit_sum", "name_en": "credit_sum", "name_ru": "credit_sum", "name_uz": "credit_sum"}, {"type": "string", "child": false, "field": "credit_expire", "name_cr": "credit_expire", "name_en": "credit_expire", "name_ru": "credit_expire", "name_uz": "credit_expire"}, {"type": "string", "child": false, "field": "export_sum", "name_cr": "export_sum", "name_en": "export_sum", "name_ru": "export_sum", "name_uz": "export_sum"}, {"type": "string", "child": false, "field": "funded_at", "name_cr": "funded_at", "name_en": "funded_at", "name_ru": "funded_at", "name_uz": "funded_at"}, {"type": "list", "child": true, "field": "products", "name_cr": "products", "name_en": "products", "name_ru": "products", "name_uz": "products", "children": [{"type": "string", "child": false, "field": "tncode", "name_cr": "tncode", "name_en": "tncode", "name_ru": "tncode", "name_uz": "tncode"}, {"type": "string", "child": false, "field": "product_name", "name_cr": "product_name", "name_en": "product_name", "name_ru": "product_name", "name_uz": "product_name"}, {"type": "string", "child": false, "field": "contract_id", "name_cr": "contract_id", "name_en": "contract_id", "name_ru": "contract_id", "name_uz": "contract_id"}]}]}
... A45: =MAX(A$2:A44)+1 -> 39 | B45: Ёшлар сиёсати ва спорт вазирлиги: "Ёшлар дафтари"га рўйхатга олинган ҳамда моддий ёрдам олган жами ё | D45: 1 | E45: ойлик | H45: subsidy.yuonger_all_report | J45: https://api.yoshlardaftari.uz/api/v2/hisob-palatasi/statistic-out-notebook-data | K45: Ёшлар ишлари агентлиги | L45: "Ёшлар дафтари"га киритилиб ёрдам олган жами ёшлар тўғрисида маълумотлар | M45: "Ёшлар дафтари"га киритилиб ёрдам олган жами ёшлар тўғрисида маълумотлар | N45: {"params": [{"type": "string", "child": false, "field": "total", "name_cr": "total", "name_en": "total", "name_ru": "total", "name_uz": "total"}, {"type": "string", "child": false, "field": "material_support", "name_cr": "material_support", "name_en": "material_support", "name_ru": "material_support", "name_uz": "material_support"}, {"type": "string", "child": false, "field": "vacational_training", "name_cr": "vacational_training", "name_en": "vacational_training", "name_ru": "vacational_training", "name_uz": "vacational_training"}, {"type": "string", "child": false, "field": "driving_training", "name_cr": "driving_training", "name_en": "driving_training", "name_ru": "driving_training", "name_uz": "driving_training"}, {"type": "string", "child": false, "field": "seeding_subsidy", "name_cr": "seeding_subsidy", "name_en": "seeding_subsidy", "name_ru": "seeding_subsidy", "name_uz": "seeding_subsidy"}, {"type": "string", "child": false, "field": "non_residential_rent", "name_cr": "non_residential_rent", "name_en": "non_residential_rent", "name_ru": "non_residential_rent", "name_uz": "non_residential_rent"}, {"type": "string", "child": false, "field": "equipment_subsidy", "name_cr": "equipment_subsidy", "name_en": "equipment_subsidy", "name_ru": "equipment_subsidy", "name_uz": "equipment_subsidy"}, {"type": "string", "child": false, "field": "edu_contract_subsidy", "name_cr": "edu_contract_subsidy", "name_en": "edu_contract_subsidy", "name_ru": "edu_contract_subsidy", "name_uz": "edu_contract_subsidy"}, {"type": "string", "child": false, "field": "kelajak_kasblari", "name_cr": "kelajak_kasblari", "name_en": "kelajak_kasblari", "name_ru": "kelajak_kasblari", "name_uz": "kelajak_kasblari"}, {"type": "string", "child": false, "field": "training_subsidy", "name_cr": "training_subsidy", "name_en": "training_subsidy", "name_ru": "training_subsidy", "name_uz": "training_subsidy"}, {"type": "string", "child": false, "field": "loc_compet_exp", "name_cr": "loc_compet_exp", "name_en": "loc_compet_exp", "name_ru": "loc_compet_exp", "name_uz": "loc_compet_exp"}, {"type": "string", "child": false, "field": "treatment_expense", "name_cr": "treatment_expense", "name_en": "treatment_expense", "name_ru": "treatment_expense", "name_uz": "treatment_expense"}, {"type": "string", "child": false, "field": "psychological_expense", "name_cr": "psychological_expense", "name_en": "psychological_expense", "name_ru": "psychological_expense", "name_uz": "psychological_expense"}, {"type": "string", "child": false, "field": "schr", "name_cr": "schr", "name_en": "schr", "name_ru": "schr", "name_uz": "schr"}, {"type": "string", "child": false, "field": "credits", "name_cr": "credits", "name_en": "credits", "name_ru": "credits", "name_uz": "credits"}, {"type": "string", "child": false, "field": "residential_rent", "name_cr": "residential_rent", "name_en": "residential_rent", "name_ru": "residential_rent", "name_uz": "residential_rent"}, {"type": "string", "child": false, "field": "employment", "name_cr": "employment", "name_en": "employment", "name_ru": "employment", "name_uz": "employment"}, {"type": "string", "child": false, "field": "entrepreneurship", "name_cr": "entrepreneurship", "name_en": "entrepreneurship", "name_ru": "entrepreneurship", "name_uz": "entrepreneurship"}, {"type": "string", "child": false, "field": "migration", "name_cr": "migration", "name_en": "migration", "name_ru": "migration", "name_uz": "migration"}, {"type": "string", "child": false, "field": "school_uniform", "name_cr": "school_uniform", "name_en": "school_uniform", "name_ru": "school_uniform", "name_uz": "school_uniform"}, {"type": "string", "child": false, "field": "passport_fee", "name_cr": "passport_fee", "name_en": "passport_fee", "name_ru": "passport_fee", "name_uz": "passport_fee"}, {"type": "string", "child": false, "field": "tour_expense", "name_cr": "tour_expense", "name_en": "tour_expense", "name_ru": "tour_expense", "name_uz": "tour_expense"}, {"type": "string", "child": false, "field": "int_compet_exp", "name_cr": "int_compet_exp", "name_en": "int_compet_exp", "name_ru": "int_compet_exp", "name_uz": "int_compet_exp"}, {"type": "string", "child": false, "field": "seperated_land", "name_cr": "seperated_land", "name_en": "seperated_land", "name_ru": "seperated_land", "name_uz": "seperated_land"}]}
A46: =MAX(A$2:A45)+1 -> 40 | B46: Ҳоким ёрдамчилари тавсияси асосида берилган жами субсидиялар тўғрисида маълумот олиш | D46: 1 | E46: кунлик | H46: mahalla.subsidiya | I46: Субсидия схемасига ўтказиб номини хоким ёрдамчи тавсия қилиш керак | J46: https://api.online-mahalla.uz/api/v1/sync/subsidy/hp
A47: =MAX(A$2:A46)+1 -> 41 | B47: Юридик шахсларга ногиронлиги бўлган шахсларни ишга мослаштирганлиги учун субсидия | D47: 1 | E47: кунлик | H47: subsidy.adjustment_jobs | J47: https://10.190.2.81/api/account-chamber/adjustment-jobs | K47: Камбағалликни қисқартириш ва бандлик вазирлиги | L47: Юридик шахсларга ногиронлиги бўлган шахсларни ишга мослаштирганлиги учун субсидия | M47: Юридик шахсларга ногиронлиги бўлган шахсларни ишга мослаштирганлиги учун субсидия | N47: {"params": [{"type": "string", "child": false, "field": "region_name", "name_cr": "region_name", "name_en": "region_name", "name_ru": "region_name", "name_uz": "region_name"}, {"type": "string", "child": false, "field": "region_soato", "name_cr": "region_soato", "name_en": "region_soato", "name_ru": "region_soato", "name_uz": "region_soato"}, {"type": "string", "child": false, "field": "district_name", "name_cr": "district_name", "name_en": "district_name", "name_ru": "district_name", "name_uz": "district_name"}, {"type": "string", "child": false, "field": "city_soato", "name_cr": "city_soato", "name_en": "city_soato", "name_ru": "city_soato", "name_uz": "city_soato"}, {"type": "string", "child": false, "field": "company_tin", "name_cr": "company_tin", "name_en": "company_tin", "name_ru": "company_tin", "name_uz": "company_tin"}, {"type": "string", "child": false, "field": "company_name", "name_cr": "company_name", "name_en": "company_name", "name_ru": "company_name", "name_uz": "company_name"}, {"type": "string", "child": false, "field": "subsidy_date", "name_cr": "subsidy_date", "name_en": "subsidy_date", "name_ru": "subsidy_date", "name_uz": "subsidy_date"}, {"type": "string", "child": false, "field": "subsidy_amount", "name_cr": "subsidy_amount", "name_en": "subsidy_amount", "name_ru": "subsidy_amount", "name_uz": "subsidy_amount"}, {"type": "string", "child": false, "field": "subsidy_name", "name_cr": "subsidy_name", "name_en": "subsidy_name", "name_ru": "subsidy_name", "name_uz": "subsidy_name"}]}
