Workbook

Sheet Риск йўналишлари
A1: "Масофавий аудит" ААТ томонидан аниқланган риск ҳолатларини назоратга олиш ҳамда уларни бартараф этилиши тўғрисида риск йўналишлари кесимида маълумот
A3: № | B3: Риск йўналиши | C3: Масъул ходим | D3: Охирги аниқланган сана | E3: Жами | K3: Охирги 16 кунликда | P3: Охирги 16 - 30 кунликда | U3: Охирги 1 - 6 ойгача | Z3: Охирги 6 - 12 ойгача | AE3: 1 йилдан ортиқ
E4: Аниқланган | F4: Назоратга олинмаган | G4: Назоратга олинган | H4: Назоратга олинган лекин ижроси таъминланмаган | I4: Шундан назоратдан ечиш учун юборилган | J4: Назоратдан ечилган | K4: Аниқланган | L4: Назоратга олинмаган | M4: Назоратга олинган | N4: Шундан назоратдан ечиш учун юборилган | O4: Назоратдан ечилган | P4: Аниқланган | Q4: Назоратга олинмаган | R4: Назоратга олинган лекин ижроси таъминланмаган | S4: Шундан назоратдан ечиш учун юборилган | T4: Назоратдан ечилган | U4: Аниқланган | V4: Назоратга олинмаган | W4: Назоратга олинган лекин ижроси таъминланмаган | X4: Шундан назоратдан ечиш учун юборилган | Y4: Назоратдан ечилган | Z4: Аниқланган | AA4: Назоратга олинмаган | AB4: Назоратга олинган лекин ижроси таъминланмаган | AC4: Шундан назоратдан ечиш учун юборилган | AD4: Назоратдан ечилган | AE4: Аниқланган | AF4: Назоратга олинмаган | AG4: Назоратга олинган лекин ижроси таъминланмаган | AH4: Шундан назоратдан ечиш учун юборилган | AI4: Назоратдан ечилган
B5: Жами: | E5: =SUM(E6:E10044) | F5: =SUM(F6:F10044) | G5: =SUM(G6:G10044) | H5: =SUM(H6:H10044) | I5: =SUM(I6:I10044) | J5: =SUM(J6:J10044) | K5: =SUM(K6:K10044) | L5: =SUM(L6:L10044) | ... AI5: =SUM(AI6:AI10044)
A6: 1 | B6: Иш ҳақининг энг кам миқдоридан кам ҳисобланган ойлик иш ҳақлари таҳлили | C6: =IFERROR(VLOOKUP(B6,Рўйхат!A:E,5,0),"") | D6: =IFERROR(VLOOKUP(B6,Рўйхат!A:F,6,0),"") | E6: =+SUMIF(Рўйхат!$A:$A,'Риск йўналишлари'!$B6,Рўйхат!G:G) | F6: =+SUMIF(Рўйхат!$A:$A,'Риск йўналишлари'!$B6,Рўйхат!H:H) | G6: =M6 | H6: =R6+W6+AB6+AG6 | I6: =+SUMIF(Рўйхат!$A:$A,'Риск йўналишлари'!$B6,Рўйхат!J:J) | J6: =+SUMIF(Рўйхат!$A:$A,'Риск йўналишлари'!$B6,Рўйхат!K:K) | K6: =+SUMIF(Рўйхат!$A:$A,'Риск йўналишлари'!$B6,Рўйхат!L:L) | L6: =+SUMIF(Рўйхат!$A:$A,'Риск йўналишлари'!$B6,Рўйхат!M:M) | M6: =+SUMIF(Рўйхат!$A:$A,'Риск йўналишлари'!$B6,Рўйхат!N:N) | N6: =+SUMIF(Рўйхат!$A:$A,'Риск йўналишлари'!$B6,Рўйхат!O:O) | O6: =+SUMIF(Рўйхат!$A:$A,'Риск йўналишлари'!$B6,Рўйхат!P:P) | P6: =+SUMIF(Рўйхат!$A:$A,'Риск йўналишлари'!$B6,Рўйхат!Q:Q) | Q6: =+SUMIF(Рўйхат!$A:$A,'Риск йўналишлари'!$B6,Рўйхат!R:R) | R6: =+SUMIF(Рўйхат!$A:$A,'Риск йўналишлари'!$B6,Рўйхат!S:S) | S6: =+SUMIF(Рўйхат!$A:$A,'Риск йўналишлари'!$B6,Рўйхат!T:T) | T6: =+SUMIF(Рўйхат!$A:$A,'Риск йўналишлари'!$B6,Рўйхат!U:U) | U6: =+SUMIF(Рўйхат!$A:$A,'Риск йўналишлари'!$B6,Рўйхат!V:V) | V6: =+SUMIF(Рўйхат!$A:$A,'Риск йўналишлари'!$B6,Рўйхат!W:W) | W6: =+SUMIF(Рўйхат!$A:$A,'Риск йўналишлари'!$B6,Рўйхат!X:X) | X6: =+SUMIF(Рўйхат!$A:$A,'Риск йўналишлари'!$B6,Рўйхат!Y:Y) | Y6: =+SUMIF(Рўйхат!$A:$A,'Риск йўналишлари'!$B6,Рўйхат!Z:Z) | Z6: =+SUMIF(Рўйхат!$A:$A,'Риск йўналишлари'!$B6,Рўйхат!AA:AA) | AA6: =+SUMIF(Рўйхат!$A:$A,'Риск йўналишлари'!$B6,Рўйхат!AB:AB) | AB6: =+SUMIF(Рўйхат!$A:$A,'Риск йўналишлари'!$B6,Рўйхат!AC:AC) | AC6: =+SUMIF(Рўйхат!$A:$A,'Риск йўналишлари'!$B6,Рўйхат!AD:AD) | AD6: =+SUMIF(Рўйхат!$A:$A,'Риск йўналишлари'!$B6,Рўйхат!AE:AE) | AE6: =+SUMIF(Рўйхат!$A:$A,'Риск йўналишлари'!$B6,Рўйхат!AF:AF) | AF6: =+SUMIF(Рўйхат!$A:$A,'Риск йўналишлари'!$B6,Рўйхат!AG:AG) | AG6: =+SUMIF(Рўйхат!$A:$A,'Риск йўналишлари'!$B6,Рўйхат!AH:AH) | AH6: =+SUMIF(Рўйхат!$A:$A,'Риск йўналишлари'!$B6,Рўйхат!AI:AI) | AI6: =+SUMIF(Рўйхат!$A:$A,'Риск йўналишлари'!$B6,Рўйхат!AJ:AJ)
A7: 2 | B7: Мансабдор шахсларга боғлиқ етказиб берувчилар билан тузилган шартномалар | C7: =IFERROR(VLOOKUP(B7,Рўйхат!A:E,5,0),"") | D7: =IFERROR(VLOOKUP(B7,Рўйхат!A:F,6,0),"") | E7: =+SUMIF(Рўйхат!$A:$A,'Риск йўналишлари'!$B7,Рўйхат!G:G) | F7: =+SUMIF(Рўйхат!$A:$A,'Риск йўналишлари'!$B7,Рўйхат!H:H) | G7: =M7 | H7: =R7+W7+AB7+AG7 | I7: =+SUMIF(Рўйхат!$A:$A,'Риск йўналишлари'!$B7,Рўйхат!J:J) | J7: =+SUMIF(Рўйхат!$A:$A,'Риск йўналишлари'!$B7,Рўйхат!K:K) | K7: =+SUMIF(Рўйхат!$A:$A,'Риск йўналишлари'!$B7,Рўйхат!L:L) | L7: =+SUMIF(Рўйхат!$A:$A,'Риск йўналишлари'!$B7,Рўйхат!M:M) | M7: =+SUMIF(Рўйхат!$A:$A,'Риск йўналишлари'!$B7,Рўйхат!N:N) | N7: =+SUMIF(Рўйхат!$A:$A,'Риск йўналишлари'!$B7,Рўйхат!O:O) | O7: =+SUMIF(Рўйхат!$A:$A,'Риск йўналишлари'!$B7,Рўйхат!P:P) | P7: =+SUMIF(Рўйхат!$A:$A,'Риск йўналишлари'!$B7,Рўйхат!Q:Q) | Q7: =+SUMIF(Рўйхат!$A:$A,'Риск йўналишлари'!$B7,Рўйхат!R:R) | R7: =+SUMIF(Рўйхат!$A:$A,'Риск йўналишлари'!$B7,Рўйхат!S:S) | S7: =+SUMIF(Рўйхат!$A:$A,'Риск йўналишлари'!$B7,Рўйхат!T:T) | T7: =+SUMIF(Рўйхат!$A:$A,'Риск йўналишлари'!$B7,Рўйхат!U:U) | U7: =+SUMIF(Рўйхат!$A:$A,'Риск йўналишлари'!$B7,Рўйхат!V:V) | V7: =+SUMIF(Рўйхат!$A:$A,'Риск йўналишлари'!$B7,Рўйхат!W:W) | W7: =+SUMIF(Рўйхат!$A:$A,'Риск йўналишлари'!$B7,Рўйхат!X:X) | X7: =+SUMIF(Рўйхат!$A:$A,'Риск йўналишлари'!$B7,Рўйхат!Y:Y) | Y7: =+SUMIF(Рўйхат!$A:$A,'Риск йўналишлари'!$B7,Рўйхат!Z:Z) | Z7: =+SUMIF(Рўйхат!$A:$A,'Риск йўналишлари'!$B7,Рўйхат!AA:AA) | AA7: =+SUMIF(Рўйхат!$A:$A,'Риск йўналишлари'!$B7,Рўйхат!AB:AB) | AB7: =+SUMIF(Рўйхат!$A:$A,'Риск йўналишлари'!$B7,Рўйхат!AC:AC) | AC7: =+SUMIF(Рўйхат!$A:$A,'Риск йўналишлари'!$B7,Рўйхат!AD:AD) | AD7: =+SUMIF(Рўйхат!$A:$A,'Риск йўналишлари'!$B7,Рўйхат!AE:AE) | AE7: =+SUMIF(Рўйхат!$A:$A,'Риск йўналишлари'!$B7,Рўйхат!AF:AF) | AF7: =+SUMIF(Рўйхат!$A:$A,'Риск йўналишлари'!$B7,Рўйхат!AG:AG) | AG7: =+SUMIF(Рўйхат!$A:$A,'Риск йўналишлари'!$B7,Рўйхат!AH:AH) | AH7: =+SUMIF(Рўйхат!$A:$A,'Риск йўналишлари'!$B7,Рўйхат!AI:AI) | AI7: =+SUMIF(Рўйхат!$A:$A,'Риск йўналишлари'!$B7,Рўйхат!AJ:AJ)
A8: 3 | B8: Давлат улуши мавжуд корхоналарда непотизм таҳлили | C8: =IFERROR(VLOOKUP(B8,Рўйхат!A:E,5,0),"") | D8: =IFERROR(VLOOKUP(B8,Рўйхат!A:F,6,0),"") | E8: =+SUMIF(Рўйхат!$A:$A,'Риск йўналишлари'!$B8,Рўйхат!G:G) | F8: =+SUMIF(Рўйхат!$A:$A,'Риск йўналишлари'!$B8,Рўйхат!H:H) | G8: =M8 | H8: =R8+W8+AB8+AG8 | I8: =+SUMIF(Рўйхат!$A:$A,'Риск йўналишлари'!$B8,Рўйхат!J:J) | J8: =+SUMIF(Рўйхат!$A:$A,'Риск йўналишлари'!$B8,Рўйхат!K:K) | K8: =+SUMIF(Рўйхат!$A:$A,'Риск йўналишлари'!$B8,Рўйхат!L:L) | L8: =+SUMIF(Рўйхат!$A:$A,'Риск йўналишлари'!$B8,Рўйхат!M:M) | M8: =+SUMIF(Рўйхат!$A:$A,'Риск йўналишлари'!$B8,Рўйхат!N:N) | N8: =+SUMIF(Рўйхат!$A:$A,'Риск йўналишлари'!$B8,Рўйхат!O:O) | O8: =+SUMIF(Рўйхат!$A:$A,'Риск йўналишлари'!$B8,Рўйхат!P:P) | P8: =+SUMIF(Рўйхат!$A:$A,'Риск йўналишлари'!$B8,Рўйхат!Q:Q) | Q8: =+SUMIF(Рўйхат!$A:$A,'Риск йўналишлари'!$B8,Рўйхат!R:R) | R8: =+SUMIF(Рўйхат!$A:$A,'Риск йўналишлари'!$B8,Рўйхат!S:S) | S8: =+SUMIF(Рўйхат!$A:$A,'Риск йўналишлари'!$B8,Рўйхат!T:T) | T8: =+SUMIF(Рўйхат!$A:$A,'Риск йўналишлари'!$B8,Рўйхат!U:U) | U8: =+SUMIF(Рўйхат!$A:$A,'Риск йўналишлари'!$B8,Рўйхат!V:V) | V8: =+SUMIF(Рўйхат!$A:$A,'Риск йўналишлари'!$B8,Рўйхат!W:W) | W8: =+SUMIF(Рўйхат!$A:$A,'Риск йўналишлари'!$B8,Рўйхат!X:X) | X8: =+SUMIF(Рўйхат!$A:$A,'Риск йўналишлари'!$B8,Рўйхат!Y:Y) | Y8: =+SUMIF(Рўйхат!$A:$A,'Риск йўналишлари'!$B8,Рўйхат!Z:Z) | Z8: =+SUMIF(Рўйхат!$A:$A,'Риск йўналишлари'!$B8,Рўйхат!AA:AA) | AA8: =+SUMIF(Рўйхат!$A:$A,'Риск йўналишлари'!$B8,Рўйхат!AB:AB) | AB8: =+SUMIF(Рўйхат!$A:$A,'Риск йўналишлари'!$B8,Рўйхат!AC:AC) | AC8: =+SUMIF(Рўйхат!$A:$A,'Риск йўналишлари'!$B8,Рўйхат!AD:AD) | AD8: =+SUMIF(Рўйхат!$A:$A,'Риск йўналишлари'!$B8,Рўйхат!AE:AE) | AE8: =+SUMIF(Рўйхат!$A:$A,'Риск йўналишлари'!$B8,Рўйхат!AF:AF) | AF8: =+SUMIF(Рўйхат!$A:$A,'Риск йўналишлари'!$B8,Рўйхат!AG:AG) | AG8: =+SUMIF(Рўйхат!$A:$A,'Риск йўналишлари'!$B8,Рўйхат!AH:AH) | AH8: =+SUMIF(Рўйхат!$A:$A,'Риск йўналишлари'!$B8,Рўйхат!AI:AI) | AI8: =+SUMIF(Рўйхат!$A:$A,'Риск йўналишлари'!$B8,Рўйхат!AJ:AJ)
A9: 4 | B9: Тўғридан-тўғри шартномалар мониторинги | C9: =IFERROR(VLOOKUP(B9,Рўйхат!A:E,5,0),"") | D9: =IFERROR(VLOOKUP(B9,Рўйхат!A:F,6,0),"") | E9: =+SUMIF(Рўйхат!$A:$A,'Риск йўналишлари'!$B9,Рўйхат!G:G) | F9: =+SUMIF(Рўйхат!$A:$A,'Риск йўналишлари'!$B9,Рўйхат!H:H) | G9: =M9 | H9: =R9+W9+AB9+AG9 | I9: =+SUMIF(Рўйхат!$A:$A,'Риск йўналишлари'!$B9,Рўйхат!J:J) | J9: =+SUMIF(Рўйхат!$A:$A,'Риск йўналишлари'!$B9,Рўйхат!K:K) | K9: =+SUMIF(Рўйхат!$A:$A,'Риск йўналишлари'!$B9,Рўйхат!L:L) | L9: =+SUMIF(Рўйхат!$A:$A,'Риск йўналишлари'!$B9,Рўйхат!M:M) | M9: =+SUMIF(Рўйхат!$A:$A,'Риск йўналишлари'!$B9,Рўйхат!N:N) | N9: =+SUMIF(Рўйхат!$A:$A,'Риск йўналишлари'!$B9,Рўйхат!O:O) | O9: =+SUMIF(Рўйхат!$A:$A,'Риск йўналишлари'!$B9,Рўйхат!P:P) | P9: =+SUMIF(Рўйхат!$A:$A,'Риск йўналишлари'!$B9,Рўйхат!Q:Q) | Q9: =+SUMIF(Рўйхат!$A:$A,'Риск йўналишлари'!$B9,Рўйхат!R:R) | R9: =+SUMIF(Рўйхат!$A:$A,'Риск йўналишлари'!$B9,Рўйхат!S:S) | S9: =+SUMIF(Рўйхат!$A:$A,'Риск йўналишлари'!$B9,Рўйхат!T:T) | T9: =+SUMIF(Рўйхат!$A:$A,'Риск йўналишлари'!$B9,Рўйхат!U:U) | U9: =+SUMIF(Рўйхат!$A:$A,'Риск йўналишлари'!$B9,Рўйхат!V:V) | V9: =+SUMIF(Рўйхат!$A:$A,'Риск йўналишлари'!$B9,Рўйхат!W:W) | W9: =+SUMIF(Рўйхат!$A:$A,'Риск йўналишлари'!$B9,Рўйхат!X:X) | X9: =+SUMIF(Рўйхат!$A:$A,'Риск йўналишлари'!$B9,Рўйхат!Y:Y) | Y9: =+SUMIF(Рўйхат!$A:$A,'Риск йўналишлари'!$B9,Рўйхат!Z:Z) | Z9: =+SUMIF(Рўйхат!$A:$A,'Риск йўналишлари'!$B9,Рўйхат!AA:AA) | AA9: =+SUMIF(Рўйхат!$A:$A,'Риск йўналишлари'!$B9,Рўйхат!AB:AB) | AB9: =+SUMIF(Рўйхат!$A:$A,'Риск йўналишлари'!$B9,Рўйхат!AC:AC) | AC9: =+SUMIF(Рўйхат!$A:$A,'Риск йўналишлари'!$B9,Рўйхат!AD:AD) | AD9: =+SUMIF(Рўйхат!$A:$A,'Риск йўналишлари'!$B9,Рўйхат!AE:AE) | AE9: =+SUMIF(Рўйхат!$A:$A,'Риск йўналишлари'!$B9,Рўйхат!AF:AF) | AF9: =+SUMIF(Рўйхат!$A:$A,'Риск йўналишлари'!$B9,Рўйхат!AG:AG) | AG9: =+SUMIF(Рўйхат!$A:$A,'Риск йўналишлари'!$B9,Рўйхат!AH:AH) | AH9: =+SUMIF(Рўйхат!$A:$A,'Риск йўналишлари'!$B9,Рўйхат!AI:AI) | AI9: =+SUMIF(Рўйхат!$A:$A,'Риск йўналишлари'!$B9,Рўйхат!AJ:AJ)
A10: 5 | B10: Қишлоқ хўжалигида фойдаланилган сув ҳажми таҳлили | C10: =IFERROR(VLOOKUP(B10,Рўйхат!A:E,5,0),"") | D10: =IFERROR(VLOOKUP(B10,Рўйхат!A:F,6,0),"") | E10: =+SUMIF(Рўйхат!$A:$A,'Риск йўналишлари'!$B10,Рўйхат!G:G) | F10: =+SUMIF(Рўйхат!$A:$A,'Риск йўналишлари'!$B10,Рўйхат!H:H) | G10: =M10 | H10: =R10+W10+AB10+AG10 | I10: =+SUMIF(Рўйхат!$A:$A,'Риск йўналишлари'!$B10,Рўйхат!J:J) | J10: =+SUMIF(Рўйхат!$A:$A,'Риск йўналишлари'!$B10,Рўйхат!K:K) | K10: =+SUMIF(Рўйхат!$A:$A,'Риск йўналишлари'!$B10,Рўйхат!L:L) | L10: =+SUMIF(Рўйхат!$A:$A,'Риск йўналишлари'!$B10,Рўйхат!M:M) | M10: =+SUMIF(Рўйхат!$A:$A,'Риск йўналишлари'!$B10,Рўйхат!N:N) | N10: =+SUMIF(Рўйхат!$A:$A,'Риск йўналишлари'!$B10,Рўйхат!O:O) | O10: =+SUMIF(Рўйхат!$A:$A,'Риск йўналишлари'!$B10,Рўйхат!P:P) | P10: =+SUMIF(Рўйхат!$A:$A,'Риск йўналишлари'!$B10,Рўйхат!Q:Q) | Q10: =+SUMIF(Рўйхат!$A:$A,'Риск йўналишлари'!$B10,Рўйхат!R:R) | R10: =+SUMIF(Рўйхат!$A:$A,'Риск йўналишлари'!$B10,Рўйхат!S:S) | S10: =+SUMIF(Рўйхат!$A:$A,'Риск йўналишлари'!$B10,Рўйхат!T:T) | T10: =+SUMIF(Рўйхат!$A:$A,'Риск йўналишлари'!$B10,Рўйхат!U:U) | U10: =+SUMIF(Рўйхат!$A:$A,'Риск йўналишлари'!$B10,Рўйхат!V:V) | V10: =+SUMIF(Рўйхат!$A:$A,'Риск йўналишлари'!$B10,Рўйхат!W:W) | W10: =+SUMIF(Рўйхат!$A:$A,'Риск йўналишлари'!$B10,Рўйхат!X:X) | X10: =+SUMIF(Рўйхат!$A:$A,'Риск йўналишлари'!$B10,Рўйхат!Y:Y) | Y10: =+SUMIF(Рўйхат!$A:$A,'Риск йўналишлари'!$B10,Рўйхат!Z:Z) | Z10: =+SUMIF(Рўйхат!$A:$A,'Риск йўналишлари'!$B10,Рўйхат!AA:AA) | AA10: =+SUMIF(Рўйхат!$A:$A,'Риск йўналишлари'!$B10,Рўйхат!AB:AB) | AB10: =+SUMIF(Рўйхат!$A:$A,'Риск йўналишлари'!$B10,Рўйхат!AC:AC) | AC10: =+SUMIF(Рўйхат!$A:$A,'Риск йўналишлари'!$B10,Рўйхат!AD:AD) | AD10: =+SUMIF(Рўйхат!$A:$A,'Риск йўналишлари'!$B10,Рўйхат!AE:AE) | AE10: =+SUMIF(Рўйхат!$A:$A,'Риск йўналишлари'!$B10,Рўйхат!AF:AF) | AF10: =+SUMIF(Рўйхат!$A:$A,'Риск йўналишлари'!$B10,Рўйхат!AG:AG) | AG10: =+SUMIF(Рўйхат!$A:$A,'Риск йўналишлари'!$B10,Рўйхат!AH:AH) | AH10: =+SUMIF(Рўйхат!$A:$A,'Риск йўналишлари'!$B10,Рўйхат!AI:AI) | AI10: =+SUMIF(Рўйхат!$A:$A,'Риск йўналишлари'!$B10,Рўйхат!AJ:AJ)
A11: 6 | B11: Манфаатлар тўқнашуви (COOPERATION AI) | C11: =IFERROR(VLOOKUP(B11,Рўйхат!A:E,5,0),"") | D11: =IFERROR(VLOOKUP(B11,Рўйхат!A:F,6,0),"") | E11: =+SUMIF(Рўйхат!$A:$A,'Риск йўналишлари'!$B11,Рўйхат!G:G) | F11: =+SUMIF(Рўйхат!$A:$A,'Риск йўналишлари'!$B11,Рўйхат!H:H) | G11: =M11 | H11: =R11+W11+AB11+AG11 | I11: =+SUMIF(Рўйхат!$A:$A,'Риск йўналишлари'!$B11,Рўйхат!J:J) | J11: =+SUMIF(Рўйхат!$A:$A,'Риск йўналишлари'!$B11,Рўйхат!K:K) | K11: =+SUMIF(Рўйхат!$A:$A,'Риск йўналишлари'!$B11,Рўйхат!L:L) | L11: =+SUMIF(Рўйхат!$A:$A,'Риск йўналишлари'!$B11,Рўйхат!M:M) | M11: =+SUMIF(Рўйхат!$A:$A,'Риск йўналишлари'!$B11,Рўйхат!N:N) | N11: =+SUMIF(Рўйхат!$A:$A,'Риск йўналишлари'!$B11,Рўйхат!O:O) | O11: =+SUMIF(Рўйхат!$A:$A,'Риск йўналишлари'!$B11,Рўйхат!P:P) | P11: =+SUMIF(Рўйхат!$A:$A,'Риск йўналишлари'!$B11,Рўйхат!Q:Q) | Q11: =+SUMIF(Рўйхат!$A:$A,'Риск йўналишлари'!$B11,Рўйхат!R:R) | R11: =+SUMIF(Рўйхат!$A:$A,'Риск йўналишлари'!$B11,Рўйхат!S:S) | S11: =+SUMIF(Рўйхат!$A:$A,'Риск йўналишлари'!$B11,Рўйхат!T:T) | T11: =+SUMIF(Рўйхат!$A:$A,'Риск йўналишлари'!$B11,Рўйхат!U:U) | U11: =+SUMIF(Рўйхат!$A:$A,'Риск йўналишлари'!$B11,Рўйхат!V:V) | V11: =+SUMIF(Рўйхат!$A:$A,'Риск йўналишлари'!$B11,Рўйхат!W:W) | W11: =+SUMIF(Рўйхат!$A:$A,'Риск йўналишлари'!$B11,Рўйхат!X:X) | X11: =+SUMIF(Рўйхат!$A:$A,'Риск йўналишлари'!$B11,Рўйхат!Y:Y) | Y11: =+SUMIF(Рўйхат!$A:$A,'Риск йўналишлари'!$B11,Рўйхат!Z:Z) | Z11: =+SUMIF(Рўйхат!$A:$A,'Риск йўналишлари'!$B11,Рўйхат!AA:AA) | AA11: =+SUMIF(Рўйхат!$A:$A,'Риск йўналишлари'!$B11,Рўйхат!AB:AB) | AB11: =+SUMIF(Рўйхат!$A:$A,'Риск йўналишлари'!$B11,Рўйхат!AC:AC) | AC11: =+SUMIF(Рўйхат!$A:$A,'Риск йўналишлари'!$B11,Рўйхат!AD:AD) | AD11: =+SUMIF(Рўйхат!$A:$A,'Риск йўналишлари'!$B11,Рўйхат!AE:AE) | AE11: =+SUMIF(Рўйхат!$A:$A,'Риск йўналишлари'!$B11,Рўйхат!AF:AF) | AF11: =+SUMIF(Рўйхат!$A:$A,'Риск йўналишлари'!$B11,Рўйхат!AG:AG) | AG11: =+SUMIF(Рўйхат!$A:$A,'Риск йўналишлари'!$B11,Рўйхат!AH:AH) | AH11: =+SUMIF(Рўйхат!$A:$A,'Риск йўналишлари'!$B11,Рўйхат!AI:AI) | AI11: =+SUMIF(Рўйхат!$A:$A,'Риск йўналишлари'!$B11,Рўйхат!AJ:AJ)
A12: 7 | B12: Ундириш имкони мавжуд бўлган жисмоний шахсларнинг баланс ҳисобидан чиқарилган кредитлари таҳлили | C12: =IFERROR(VLOOKUP(B12,Рўйхат!A:E,5,0),"") | D12: =IFERROR(VLOOKUP(B12,Рўйхат!A:F,6,0),"") | E12: =+SUMIF(Рўйхат!$A:$A,'Риск йўналишлари'!$B12,Рўйхат!G:G) | F12: =+SUMIF(Рўйхат!$A:$A,'Риск йўналишлари'!$B12,Рўйхат!H:H) | G12: =M12 | H12: =R12+W12+AB12+AG12 | I12: =+SUMIF(Рўйхат!$A:$A,'Риск йўналишлари'!$B12,Рўйхат!J:J) | J12: =+SUMIF(Рўйхат!$A:$A,'Риск йўналишлари'!$B12,Рўйхат!K:K) | K12: =+SUMIF(Рўйхат!$A:$A,'Риск йўналишлари'!$B12,Рўйхат!L:L) | L12: =+SUMIF(Рўйхат!$A:$A,'Риск йўналишлари'!$B12,Рўйхат!M:M) | M12: =+SUMIF(Рўйхат!$A:$A,'Риск йўналишлари'!$B12,Рўйхат!N:N) | N12: =+SUMIF(Рўйхат!$A:$A,'Риск йўналишлари'!$B12,Рўйхат!O:O) | O12: =+SUMIF(Рўйхат!$A:$A,'Риск йўналишлари'!$B12,Рўйхат!P:P) | P12: =+SUMIF(Рўйхат!$A:$A,'Риск йўналишлари'!$B12,Рўйхат!Q:Q) | Q12: =+SUMIF(Рўйхат!$A:$A,'Риск йўналишлари'!$B12,Рўйхат!R:R) | R12: =+SUMIF(Рўйхат!$A:$A,'Риск йўналишлари'!$B12,Рўйхат!S:S) | S12: =+SUMIF(Рўйхат!$A:$A,'Риск йўналишлари'!$B12,Рўйхат!T:T) | T12: =+SUMIF(Рўйхат!$A:$A,'Риск йўналишлари'!$B12,Рўйхат!U:U) | U12: =+SUMIF(Рўйхат!$A:$A,'Риск йўналишлари'!$B12,Рўйхат!V:V) | V12: =+SUMIF(Рўйхат!$A:$A,'Риск йўналишлари'!$B12,Рўйхат!W:W) | W12: =+SUMIF(Рўйхат!$A:$A,'Риск йўналишлари'!$B12,Рўйхат!X:X) | X12: =+SUMIF(Рўйхат!$A:$A,'Риск йўналишлари'!$B12,Рўйхат!Y:Y) | Y12: =+SUMIF(Рўйхат!$A:$A,'Риск йўналишлари'!$B12,Рўйхат!Z:Z) | Z12: =+SUMIF(Рўйхат!$A:$A,'Риск йўналишлари'!$B12,Рўйхат!AA:AA) | AA12: =+SUMIF(Рўйхат!$A:$A,'Риск йўналишлари'!$B12,Рўйхат!AB:AB) | AB12: =+SUMIF(Рўйхат!$A:$A,'Риск йўналишлари'!$B12,Рўйхат!AC:AC) | AC12: =+SUMIF(Рўйхат!$A:$A,'Риск йўналишлари'!$B12,Рўйхат!AD:AD) | AD12: =+SUMIF(Рўйхат!$A:$A,'Риск йўналишлари'!$B12,Рўйхат!AE:AE) | AE12: =+SUMIF(Рўйхат!$A:$A,'Риск йўналишлари'!$B12,Рўйхат!AF:AF) | AF12: =+SUMIF(Рўйхат!$A:$A,'Риск йўналишлари'!$B12,Рўйхат!AG:AG) | AG12: =+SUMIF(Рўйхат!$A:$A,'Риск йўналишлари'!$B12,Рўйхат!AH:AH) | AH12: =+SUMIF(Рўйхат!$A:$A,'Риск йўналишлари'!$B12,Рўйхат!AI:AI) | AI12: =+SUMIF(Рўйхат!$A:$A,'Риск йўналишлари'!$B12,Рўйхат!AJ:AJ)
A13: 8 | B13: Рейтинг бали шаклланишида ишчи ходим сони таҳлили | C13: =IFERROR(VLOOKUP(B13,Рўйхат!A:E,5,0),"") | D13: =IFERROR(VLOOKUP(B13,Рўйхат!A:F,6,0),"") | E13: =+SUMIF(Рўйхат!$A:$A,'Риск йўналишлари'!$B13,Рўйхат!G:G) | F13: =+SUMIF(Рўйхат!$A:$A,'Риск йўналишлари'!$B13,Рўйхат!H:H) | G13: =M13 | H13: =R13+W13+AB13+AG13 | I13: =+SUMIF(Рўйхат!$A:$A,'Риск йўналишлари'!$B13,Рўйхат!J:J) | J13: =+SUMIF(Рўйхат!$A:$A,'Риск йўналишлари'!$B13,Рўйхат!K:K) | K13: =+SUMIF(Рўйхат!$A:$A,'Риск йўналишлари'!$B13,Рўйхат!L:L) | L13: =+SUMIF(Рўйхат!$A:$A,'Риск йўналишлари'!$B13,Рўйхат!M:M) | M13: =+SUMIF(Рўйхат!$A:$A,'Риск йўналишлари'!$B13,Рўйхат!N:N) | N13: =+SUMIF(Рўйхат!$A:$A,'Риск йўналишлари'!$B13,Рўйхат!O:O) | O13: =+SUMIF(Рўйхат!$A:$A,'Риск йўналишлари'!$B13,Рўйхат!P:P) | P13: =+SUMIF(Рўйхат!$A:$A,'Риск йўналишлари'!$B13,Рўйхат!Q:Q) | Q13: =+SUMIF(Рўйхат!$A:$A,'Риск йўналишлари'!$B13,Рўйхат!R:R) | R13: =+SUMIF(Рўйхат!$A:$A,'Риск йўналишлари'!$B13,Рўйхат!S:S) | S13: =+SUMIF(Рўйхат!$A:$A,'Риск йўналишлари'!$B13,Рўйхат!T:T) | T13: =+SUMIF(Рўйхат!$A:$A,'Риск йўналишлари'!$B13,Рўйхат!U:U) | U13: =+SUMIF(Рўйхат!$A:$A,'Риск йўналишлари'!$B13,Рўйхат!V:V) | V13: =+SUMIF(Рўйхат!$A:$A,'Риск йўналишлари'!$B13,Рўйхат!W:W) | W13: =+SUMIF(Рўйхат!$A:$A,'Риск йўналишлари'!$B13,Рўйхат!X:X) | X13: =+SUMIF(Рўйхат!$A:$A,'Риск йўналишлари'!$B13,Рўйхат!Y:Y) | Y13: =+SUMIF(Рўйхат!$A:$A,'Риск йўналишлари'!$B13,Рўйхат!Z:Z) | Z13: =+SUMIF(Рўйхат!$A:$A,'Риск йўналишлари'!$B13,Рўйхат!AA:AA) | AA13: =+SUMIF(Рўйхат!$A:$A,'Риск йўналишлари'!$B13,Рўйхат!AB:AB) | AB13: =+SUMIF(Рўйхат!$A:$A,'Риск йўналишлари'!$B13,Рўйхат!AC:AC) | AC13: =+SUMIF(Рўйхат!$A:$A,'Риск йўналишлари'!$B13,Рўйхат!AD:AD) | AD13: =+SUMIF(Рўйхат!$A:$A,'Риск йўналишлари'!$B13,Рўйхат!AE:AE) | AE13: =+SUMIF(Рўйхат!$A:$A,'Риск йўналишлари'!$B13,Рўйхат!AF:AF) | AF13: =+SUMIF(Рўйхат!$A:$A,'Риск йўналишлари'!$B13,Рўйхат!AG:AG) | AG13: =+SUMIF(Рўйхат!$A:$A,'Риск йўналишлари'!$B13,Рўйхат!AH:AH) | AH13: =+SUMIF(Рўйхат!$A:$A,'Риск йўналишлари'!$B13,Рўйхат!AI:AI) | AI13: =+SUMIF(Рўйхат!$A:$A,'Риск йўналишлари'!$B13,Рўйхат!AJ:AJ)
A14: 9 | B14: Импорт маҳсулотлари таҳлили | C14: =IFERROR(VLOOKUP(B14,Рўйхат!A:E,5,0),"") | D14: =IFERROR(VLOOKUP(B14,Рўйхат!A:F,6,0),"") | E14: =+SUMIF(Рўйхат!$A:$A,'Риск йўналишлари'!$B14,Рўйхат!G:G) | F14: =+SUMIF(Рўйхат!$A:$A,'Риск йўналишлари'!$B14,Рўйхат!H:H) | G14: =M14 | H14: =R14+W14+AB14+AG14 | I14: =+SUMIF(Рўйхат!$A:$A,'Риск йўналишлари'!$B14,Рўйхат!J:J) | J14: =+SUMIF(Рўйхат!$A:$A,'Риск йўналишлари'!$B14,Рўйхат!K:K) | K14: =+SUMIF(Рўйхат!$A:$A,'Риск йўналишлари'!$B14,Рўйхат!L:L) | L14: =+SUMIF(Рўйхат!$A:$A,'Риск йўналишлари'!$B14,Рўйхат!M:M) | M14: =+SUMIF(Рўйхат!$A:$A,'Риск йўналишлари'!$B14,Рўйхат!N:N) | N14: =+SUMIF(Рўйхат!$A:$A,'Риск йўналишлари'!$B14,Рўйхат!O:O) | O14: =+SUMIF(Рўйхат!$A:$A,'Риск йўналишлари'!$B14,Рўйхат!P:P) | P14: =+SUMIF(Рўйхат!$A:$A,'Риск йўналишлари'!$B14,Рўйхат!Q:Q) | Q14: =+SUMIF(Рўйхат!$A:$A,'Риск йўналишлари'!$B14,Рўйхат!R:R) | R14: =+SUMIF(Рўйхат!$A:$A,'Риск йўналишлари'!$B14,Рўйхат!S:S) | S14: =+SUMIF(Рўйхат!$A:$A,'Риск йўналишлари'!$B14,Рўйхат!T:T) | T14: =+SUMIF(Рўйхат!$A:$A,'Риск йўналишлари'!$B14,Рўйхат!U:U) | U14: =+SUMIF(Рўйхат!$A:$A,'Риск йўналишлари'!$B14,Рўйхат!V:V) | V14: =+SUMIF(Рўйхат!$A:$A,'Риск йўналишлари'!$B14,Рўйхат!W:W) | W14: =+SUMIF(Рўйхат!$A:$A,'Риск йўналишлари'!$B14,Рўйхат!X:X) | X14: =+SUMIF(Рўйхат!$A:$A,'Риск йўналишлари'!$B14,Рўйхат!Y:Y) | Y14: =+SUMIF(Рўйхат!$A:$A,'Риск йўналишлари'!$B14,Рўйхат!Z:Z) | Z14: =+SUMIF(Рўйхат!$A:$A,'Риск йўналишлари'!$B14,Рўйхат!AA:AA) | AA14: =+SUMIF(Рўйхат!$A:$A,'Риск йўналишлари'!$B14,Рўйхат!AB:AB) | AB14: =+SUMIF(Рўйхат!$A:$A,'Риск йўналишлари'!$B14,Рўйхат!AC:AC) | AC14: =+SUMIF(Рўйхат!$A:$A,'Риск йўналишлари'!$B14,Рўйхат!AD:AD) | AD14: =+SUMIF(Рўйхат!$A:$A,'Риск йўналишлари'!$B14,Рўйхат!AE:AE) | AE14: =+SUMIF(Рўйхат!$A:$A,'Риск йўналишлари'!$B14,Рўйхат!AF:AF) | AF14: =+SUMIF(Рўйхат!$A:$A,'Риск йўналишлари'!$B14,Рўйхат!AG:AG) | AG14: =+SUMIF(Рўйхат!$A:$A,'Риск йўналишлари'!$B14,Рўйхат!AH:AH) | AH14: =+SUMIF(Рўйхат!$A:$A,'Риск йўналишлари'!$B14,Рўйхат!AI:AI) | AI14: =+SUMIF(Рўйхат!$A:$A,'Риск йўналишлари'!$B14,Рўйхат!AJ:AJ)
A15: 10 | B15: Бюджет ташкилотларида непотизм ҳолатлари таҳлили | C15: =IFERROR(VLOOKUP(B15,Рўйхат!A:E,5,0),"") | D15: =IFERROR(VLOOKUP(B15,Рўйхат!A:F,6,0),"") | E15: =+SUMIF(Рўйхат!$A:$A,'Риск йўналишлари'!$B15,Рўйхат!G:G) | F15: =+SUMIF(Рўйхат!$A:$A,'Риск йўналишлари'!$B15,Рўйхат!H:H) | G15: =M15 | H15: =R15+W15+AB15+AG15 | I15: =+SUMIF(Рўйхат!$A:$A,'Риск йўналишлари'!$B15,Рўйхат!J:J) | J15: =+SUMIF(Рўйхат!$A:$A,'Риск йўналишлари'!$B15,Рўйхат!K:K) | K15: =+SUMIF(Рўйхат!$A:$A,'Риск йўналишлари'!$B15,Рўйхат!L:L) | L15: =+SUMIF(Рўйхат!$A:$A,'Риск йўналишлари'!$B15,Рўйхат!M:M) | M15: =+SUMIF(Рўйхат!$A:$A,'Риск йўналишлари'!$B15,Рўйхат!N:N) | N15: =+SUMIF(Рўйхат!$A:$A,'Риск йўналишлари'!$B15,Рўйхат!O:O) | O15: =+SUMIF(Рўйхат!$A:$A,'Риск йўналишлари'!$B15,Рўйхат!P:P) | P15: =+SUMIF(Рўйхат!$A:$A,'Риск йўналишлари'!$B15,Рўйхат!Q:Q) | Q15: =+SUMIF(Рўйхат!$A:$A,'Риск йўналишлари'!$B15,Рўйхат!R:R) | R15: =+SUMIF(Рўйхат!$A:$A,'Риск йўналишлари'!$B15,Рўйхат!S:S) | S15: =+SUMIF(Рўйхат!$A:$A,'Риск йўналишлари'!$B15,Рўйхат!T:T) | T15: =+SUMIF(Рўйхат!$A:$A,'Риск йўналишлари'!$B15,Рўйхат!U:U) | U15: =+SUMIF(Рўйхат!$A:$A,'Риск йўналишлари'!$B15,Рўйхат!V:V) | V15: =+SUMIF(Рўйхат!$A:$A,'Риск йўналишлари'!$B15,Рўйхат!W:W) | W15: =+SUMIF(Рўйхат!$A:$A,'Риск йўналишлари'!$B15,Рўйхат!X:X) | X15: =+SUMIF(Рўйхат!$A:$A,'Риск йўналишлари'!$B15,Рўйхат!Y:Y) | Y15: =+SUMIF(Рўйхат!$A:$A,'Риск йўналишлари'!$B15,Рўйхат!Z:Z) | Z15: =+SUMIF(Рўйхат!$A:$A,'Риск йўналишлари'!$B15,Рўйхат!AA:AA) | AA15: =+SUMIF(Рўйхат!$A:$A,'Риск йўналишлари'!$B15,Рўйхат!AB:AB) | AB15: =+SUMIF(Рўйхат!$A:$A,'Риск йўналишлари'!$B15,Рўйхат!AC:AC) | AC15: =+SUMIF(Рўйхат!$A:$A,'Риск йўналишлари'!$B15,Рўйхат!AD:AD) | AD15: =+SUMIF(Рўйхат!$A:$A,'Риск йўналишлари'!$B15,Рўйхат!AE:AE) | AE15: =+SUMIF(Рўйхат!$A:$A,'Риск йўналишлари'!$B15,Рўйхат!AF:AF) | AF15: =+SUMIF(Рўйхат!$A:$A,'Риск йўналишлари'!$B15,Рўйхат!AG:AG) | AG15: =+SUMIF(Рўйхат!$A:$A,'Риск йўналишлари'!$B15,Рўйхат!AH:AH) | AH15: =+SUMIF(Рўйхат!$A:$A,'Риск йўналишлари'!$B15,Рўйхат!AI:AI) | AI15: =+SUMIF(Рўйхат!$A:$A,'Риск йўналишлари'!$B15,Рўйхат!AJ:AJ)
A16: 11 | B16: Ундириш имкони мавжуд бўлган жисмоний шахсларнинг муаммоли кредитлари таҳлили | C16: =IFERROR(VLOOKUP(B16,Рўйхат!A:E,5,0),"") | D16: =IFERROR(VLOOKUP(B16,Рўйхат!A:F,6,0),"") | E16: =+SUMIF(Рўйхат!$A:$A,'Риск йўналишлари'!$B16,Рўйхат!G:G) | F16: =+SUMIF(Рўйхат!$A:$A,'Риск йўналишлари'!$B16,Рўйхат!H:H) | G16: =M16 | H16: =R16+W16+AB16+AG16 | I16: =+SUMIF(Рўйхат!$A:$A,'Риск йўналишлари'!$B16,Рўйхат!J:J) | J16: =+SUMIF(Рўйхат!$A:$A,'Риск йўналишлари'!$B16,Рўйхат!K:K) | K16: =+SUMIF(Рўйхат!$A:$A,'Риск йўналишлари'!$B16,Рўйхат!L:L) | L16: =+SUMIF(Рўйхат!$A:$A,'Риск йўналишлари'!$B16,Рўйхат!M:M) | M16: =+SUMIF(Рўйхат!$A:$A,'Риск йўналишлари'!$B16,Рўйхат!N:N) | N16: =+SUMIF(Рўйхат!$A:$A,'Риск йўналишлари'!$B16,Рўйхат!O:O) | O16: =+SUMIF(Рўйхат!$A:$A,'Риск йўналишлари'!$B16,Рўйхат!P:P) | P16: =+SUMIF(Рўйхат!$A:$A,'Риск йўналишлари'!$B16,Рўйхат!Q:Q) | Q16: =+SUMIF(Рўйхат!$A:$A,'Риск йўналишлари'!$B16,Рўйхат!R:R) | R16: =+SUMIF(Рўйхат!$A:$A,'Риск йўналишлари'!$B16,Рўйхат!S:S) | S16: =+SUMIF(Рўйхат!$A:$A,'Риск йўналишлари'!$B16,Рўйхат!T:T) | T16: =+SUMIF(Рўйхат!$A:$A,'Риск йўналишлари'!$B16,Рўйхат!U:U) | U16: =+SUMIF(Рўйхат!$A:$A,'Риск йўналишлари'!$B16,Рўйхат!V:V) | V16: =+SUMIF(Рўйхат!$A:$A,'Риск йўналишлари'!$B16,Рўйхат!W:W) | W16: =+SUMIF(Рўйхат!$A:$A,'Риск йўналишлари'!$B16,Рўйхат!X:X) | X16: =+SUMIF(Рўйхат!$A:$A,'Риск йўналишлари'!$B16,Рўйхат!Y:Y) | Y16: =+SUMIF(Рўйхат!$A:$A,'Риск йўналишлари'!$B16,Рўйхат!Z:Z) | Z16: =+SUMIF(Рўйхат!$A:$A,'Риск йўналишлари'!$B16,Рўйхат!AA:AA) | AA16: =+SUMIF(Рўйхат!$A:$A,'Риск йўналишлари'!$B16,Рўйхат!AB:AB) | AB16: =+SUMIF(Рўйхат!$A:$A,'Риск йўналишлари'!$B16,Рўйхат!AC:AC) | AC16: =+SUMIF(Рўйхат!$A:$A,'Риск йўналишлари'!$B16,Рўйхат!AD:AD) | AD16: =+SUMIF(Рўйхат!$A:$A,'Риск йўналишлари'!$B16,Рўйхат!AE:AE) | AE16: =+SUMIF(Рўйхат!$A:$A,'Риск йўналишлари'!$B16,Рўйхат!AF:AF) | AF16: =+SUMIF(Рўйхат!$A:$A,'Риск йўналишлари'!$B16,Рўйхат!AG:AG) | AG16: =+SUMIF(Рўйхат!$A:$A,'Риск йўналишлари'!$B16,Рўйхат!AH:AH) | AH16: =+SUMIF(Рўйхат!$A:$A,'Риск йўналишлари'!$B16,Рўйхат!AI:AI) | AI16: =+SUMIF(Рўйхат!$A:$A,'Риск йўналишлари'!$B16,Рўйхат!AJ:AJ)
A17: 12 | B17: Бюджет ташкилотларида ишловчиларнинг 4 ва ундан ортиқ даромад манбаига эга фуқаролар | C17: =IFERROR(VLOOKUP(B17,Рўйхат!A:E,5,0),"") | D17: =IFERROR(VLOOKUP(B17,Рўйхат!A:F,6,0),"") | E17: =+SUMIF(Рўйхат!$A:$A,'Риск йўналишлари'!$B17,Рўйхат!G:G) | F17: =+SUMIF(Рўйхат!$A:$A,'Риск йўналишлари'!$B17,Рўйхат!H:H) | G17: =M17 | H17: =R17+W17+AB17+AG17 | I17: =+SUMIF(Рўйхат!$A:$A,'Риск йўналишлари'!$B17,Рўйхат!J:J) | J17: =+SUMIF(Рўйхат!$A:$A,'Риск йўналишлари'!$B17,Рўйхат!K:K) | K17: =+SUMIF(Рўйхат!$A:$A,'Риск йўналишлари'!$B17,Рўйхат!L:L) | L17: =+SUMIF(Рўйхат!$A:$A,'Риск йўналишлари'!$B17,Рўйхат!M:M) | M17: =+SUMIF(Рўйхат!$A:$A,'Риск йўналишлари'!$B17,Рўйхат!N:N) | N17: =+SUMIF(Рўйхат!$A:$A,'Риск йўналишлари'!$B17,Рўйхат!O:O) | O17: =+SUMIF(Рўйхат!$A:$A,'Риск йўналишлари'!$B17,Рўйхат!P:P) | P17: =+SUMIF(Рўйхат!$A:$A,'Риск йўналишлари'!$B17,Рўйхат!Q:Q) | Q17: =+SUMIF(Рўйхат!$A:$A,'Риск йўналишлари'!$B17,Рўйхат!R:R) | R17: =+SUMIF(Рўйхат!$A:$A,'Риск йўналишлари'!$B17,Рўйхат!S:S) | S17: =+SUMIF(Рўйхат!$A:$A,'Риск йўналишлари'!$B17,Рўйхат!T:T) | T17: =+SUMIF(Рўйхат!$A:$A,'Риск йўналишлари'!$B17,Рўйхат!U:U) | U17: =+SUMIF(Рўйхат!$A:$A,'Риск йўналишлари'!$B17,Рўйхат!V:V) | V17: =+SUMIF(Рўйхат!$A:$A,'Риск йўналишлари'!$B17,Рўйхат!W:W) | W17: =+SUMIF(Рўйхат!$A:$A,'Риск йўналишлари'!$B17,Рўйхат!X:X) | X17: =+SUMIF(Рўйхат!$A:$A,'Риск йўналишлари'!$B17,Рўйхат!Y:Y) | Y17: =+SUMIF(Рўйхат!$A:$A,'Риск йўналишлари'!$B17,Рўйхат!Z:Z) | Z17: =+SUMIF(Рўйхат!$A:$A,'Риск йўналишлари'!$B17,Рўйхат!AA:AA) | AA17: =+SUMIF(Рўйхат!$A:$A,'Риск йўналишлари'!$B17,Рўйхат!AB:AB) | AB17: =+SUMIF(Рўйхат!$A:$A,'Риск йўналишлари'!$B17,Рўйхат!AC:AC) | AC17: =+SUMIF(Рўйхат!$A:$A,'Риск йўналишлари'!$B17,Рўйхат!AD:AD) | AD17: =+SUMIF(Рўйхат!$A:$A,'Риск йўналишлари'!$B17,Рўйхат!AE:AE) | AE17: =+SUMIF(Рўйхат!$A:$A,'Риск йўналишлари'!$B17,Рўйхат!AF:AF) | AF17: =+SUMIF(Рўйхат!$A:$A,'Риск йўналишлари'!$B17,Рўйхат!AG:AG) | AG17: =+SUMIF(Рўйхат!$A:$A,'Риск йўналишлари'!$B17,Рўйхат!AH:AH) | AH17: =+SUMIF(Рўйхат!$A:$A,'Риск йўналишлари'!$B17,Рўйхат!AI:AI) | AI17: =+SUMIF(Рўйхат!$A:$A,'Риск йўналишлари'!$B17,Рўйхат!AJ:AJ)
... A98: 93 | B98: Лицензияга эга бўлмаган етказиб берувчилардан дори воситаларининг хариди | C98: =IFERROR(VLOOKUP(B98,Рўйхат!A:E,5,0),"") | D98: =IFERROR(VLOOKUP(B98,Рўйхат!A:F,6,0),"") | E98: =+SUMIF(Рўйхат!$A:$A,'Риск йўналишлари'!$B98,Рўйхат!G:G) | F98: =+SUMIF(Рўйхат!$A:$A,'Риск йўналишлари'!$B98,Рўйхат!H:H) | G98: =M98 | H98: =R98+W98+AB98+AG98 | I98: =+SUMIF(Рўйхат!$A:$A,'Риск йўналишлари'!$B98,Рўйхат!J:J) | J98: =+SUMIF(Рўйхат!$A:$A,'Риск йўналишлари'!$B98,Рўйхат!K:K) | K98: =+SUMIF(Рўйхат!$A:$A,'Риск йўналишлари'!$B98,Рўйхат!L:L) | L98: =+SUMIF(Рўйхат!$A:$A,'Риск йўналишлари'!$B98,Рўйхат!M:M) | M98: =+SUMIF(Рўйхат!$A:$A,'Риск йўналишлари'!$B98,Рўйхат!N:N) | N98: =+SUMIF(Рўйхат!$A:$A,'Риск йўналишлари'!$B98,Рўйхат!O:O) | O98: =+SUMIF(Рўйхат!$A:$A,'Риск йўналишлари'!$B98,Рўйхат!P:P) | P98: =+SUMIF(Рўйхат!$A:$A,'Риск йўналишлари'!$B98,Рўйхат!Q:Q) | Q98: =+SUMIF(Рўйхат!$A:$A,'Риск йўналишлари'!$B98,Рўйхат!R:R) | R98: =+SUMIF(Рўйхат!$A:$A,'Риск йўналишлари'!$B98,Рўйхат!S:S) | S98: =+SUMIF(Рўйхат!$A:$A,'Риск йўналишлари'!$B98,Рўйхат!T:T) | T98: =+SUMIF(Рўйхат!$A:$A,'Риск йўналишлари'!$B98,Рўйхат!U:U) | U98: =+SUMIF(Рўйхат!$A:$A,'Риск йўналишлари'!$B98,Рўйхат!V:V) | V98: =+SUMIF(Рўйхат!$A:$A,'Риск йўналишлари'!$B98,Рўйхат!W:W) | W98: =+SUMIF(Рўйхат!$A:$A,'Риск йўналишлари'!$B98,Рўйхат!X:X) | X98: =+SUMIF(Рўйхат!$A:$A,'Риск йўналишлари'!$B98,Рўйхат!Y:Y) | Y98: =+SUMIF(Рўйхат!$A:$A,'Риск йўналишлари'!$B98,Рўйхат!Z:Z) | Z98: =+SUMIF(Рўйхат!$A:$A,'Риск йўналишлари'!$B98,Рўйхат!AA:AA) | AA98: =+SUMIF(Рўйхат!$A:$A,'Риск йўналишлари'!$B98,Рўйхат!AB:AB) | AB98: =+SUMIF(Рўйхат!$A:$A,'Риск йўналишлари'!$B98,Рўйхат!AC:AC) | AC98: =+SUMIF(Рўйхат!$A:$A,'Риск йўналишлари'!$B98,Рўйхат!AD:AD) | AD98: =+SUMIF(Рўйхат!$A:$A,'Риск йўналишлари'!$B98,Рўйхат!AE:AE) | AE98: =+SUMIF(Рўйхат!$A:$A,'Риск йўналишлари'!$B98,Рўйхат!AF:AF) | AF98: =+SUMIF(Рўйхат!$A:$A,'Риск йўналишлари'!$B98,Рўйхат!AG:AG) | AG98: =+SUMIF(Рўйхат!$A:$A,'Риск йўналишлари'!$B98,Рўйхат!AH:AH) | AH98: =+SUMIF(Рўйхат!$A:$A,'Риск йўналишлари'!$B98,Рўйхат!AI:AI) | AI98: =+SUMIF(Рўйхат!$A:$A,'Риск йўналишлари'!$B98,Рўйхат!AJ:AJ)

Sheet Вазирликлар кесимида
A1: "Масофавий аудит" ААТ томонидан аниқланган риск ҳолатларини назоратга олиш ҳамда уларни бартараф этилиши тўғрисида вазирлик ва идоралар кесимида маълумот
A3: № | B3: Масъул ходим | C3: Тизим фойдаланувчилари сони | D3: Масъул ходим | E3: Жами | K3: Охирги 16 кунликда | P3: Охирги 16 - 30 кунликда | U3: Охирги 1 - 6 ойгача | Z3: Охирги 6 - 12 ойгача | AE3: 1 йилдан ортиқ
E4: Аниқланган | F4: Назоратга олинмаган | G4: Назоратга олинган | H4: Назоратга олинган лекин ижроси таъминланмаган | I4: Шундан назоратдан ечиш учун юборилган | J4: Назоратдан ечилган | K4: Аниқланган | L4: Назоратга олинмаган | M4: Назоратга олинган | N4: Шундан назоратдан ечиш учун юборилган | O4: Назоратдан ечилган | P4: Аниқланган | Q4: Назоратга олинмаган | R4: Назоратга олинган лекин ижроси таъминланмаган | S4: Шундан назоратдан ечиш учун юборилган | T4: Назоратдан ечилган | U4: Аниқланган | V4: Назоратга олинмаган | W4: Назоратга олинган лекин ижроси таъминланмаган | X4: Шундан назоратдан ечиш учун юборилган | Y4: Назоратдан ечилган | Z4: Аниқланган | AA4: Назоратга олинмаган | AB4: Назоратга олинган лекин ижроси таъминланмаган | AC4: Шундан назоратдан ечиш учун юборилган | AD4: Назоратдан ечилган | AE4: Аниқланган | AF4: Назоратга олинмаган | AG4: Назоратга олинган лекин ижроси таъминланмаган | AH4: Шундан назоратдан ечиш учун юборилган | AI4: Назоратдан ечилган
B5: Жами: | C5: =SUM(C6:C10013) | E5: =SUM(E6:E10026) | F5: =SUM(F6:F10026) | G5: =SUM(G6:G10026) | H5: =SUM(H6:H10026) | I5: =SUM(I6:I10026) | J5: =SUM(J6:J10026) | K5: =SUM(K6:K10026) | L5: =SUM(L6:L10026) | ... AI5: =SUM(AI6:AI10026)
A6: 1 | B6: Солиқ қўмитаси | C6: =IF(IFERROR(VLOOKUP(B6,Рўйхат!C:E,2,0),"")="[NULL]","",IFERROR(VLOOKUP(B6,Рўйхат!C:E,2,0),"")) | D6: =IFERROR(VLOOKUP(B6,Рўйхат!C:E,3,0),"") | E6: =+SUMIF(Рўйхат!$C:$C,$B6,Рўйхат!G:G) | F6: =+SUMIF(Рўйхат!$C:$C,$B6,Рўйхат!H:H) | G6: =M6 | H6: =R6+W6+AB6+AG6 | I6: =+SUMIF(Рўйхат!$C:$C,$B6,Рўйхат!J:J) | J6: =+SUMIF(Рўйхат!$C:$C,$B6,Рўйхат!K:K) | K6: =+SUMIF(Рўйхат!$C:$C,$B6,Рўйхат!L:L) | L6: =+SUMIF(Рўйхат!$C:$C,$B6,Рўйхат!M:M) | M6: =+SUMIF(Рўйхат!$C:$C,$B6,Рўйхат!N:N) | N6: =+SUMIF(Рўйхат!$C:$C,$B6,Рўйхат!O:O) | O6: =+SUMIF(Рўйхат!$C:$C,$B6,Рўйхат!P:P) | P6: =+SUMIF(Рўйхат!$C:$C,$B6,Рўйхат!Q:Q) | Q6: =+SUMIF(Рўйхат!$C:$C,$B6,Рўйхат!R:R) | R6: =+SUMIF(Рўйхат!$C:$C,$B6,Рўйхат!S:S) | S6: =+SUMIF(Рўйхат!$C:$C,$B6,Рўйхат!T:T) | T6: =+SUMIF(Рўйхат!$C:$C,$B6,Рўйхат!U:U) | U6: =+SUMIF(Рўйхат!$C:$C,$B6,Рўйхат!V:V) | V6: =+SUMIF(Рўйхат!$C:$C,$B6,Рўйхат!W:W) | W6: =+SUMIF(Рўйхат!$C:$C,$B6,Рўйхат!X:X) | X6: =+SUMIF(Рўйхат!$C:$C,$B6,Рўйхат!Y:Y) | Y6: =+SUMIF(Рўйхат!$C:$C,$B6,Рўйхат!Z:Z) | Z6: =+SUMIF(Рўйхат!$C:$C,$B6,Рўйхат!AA:AA) | AA6: =+SUMIF(Рўйхат!$C:$C,$B6,Рўйхат!AB:AB) | AB6: =+SUMIF(Рўйхат!$C:$C,$B6,Рўйхат!AC:AC) | AC6: =+SUMIF(Рўйхат!$C:$C,$B6,Рўйхат!AD:AD) | AD6: =+SUMIF(Рўйхат!$C:$C,$B6,Рўйхат!AE:AE) | AE6: =+SUMIF(Рўйхат!$C:$C,$B6,Рўйхат!AF:AF) | AF6: =+SUMIF(Рўйхат!$C:$C,$B6,Рўйхат!AG:AG) | AG6: =+SUMIF(Рўйхат!$C:$C,$B6,Рўйхат!AH:AH) | AH6: =+SUMIF(Рўйхат!$C:$C,$B6,Рўйхат!AI:AI) | AI6: =+SUMIF(Рўйхат!$C:$C,$B6,Рўйхат!AJ:AJ)
A7: =+A6+1 | B7: Мактабгача ва мактаб таълими вазирлиги | C7: =IF(IFERROR(VLOOKUP(B7,Рўйхат!C:E,2,0),"")="[NULL]","",IFERROR(VLOOKUP(B7,Рўйхат!C:E,2,0),"")) | D7: =IFERROR(VLOOKUP(B7,Рўйхат!C:E,3,0),"") | E7: =+SUMIF(Рўйхат!$C:$C,$B7,Рўйхат!G:G) | F7: =+SUMIF(Рўйхат!$C:$C,$B7,Рўйхат!H:H) | G7: =M7 | H7: =R7+W7+AB7+AG7 | I7: =+SUMIF(Рўйхат!$C:$C,$B7,Рўйхат!J:J) | J7: =+SUMIF(Рўйхат!$C:$C,$B7,Рўйхат!K:K) | K7: =+SUMIF(Рўйхат!$C:$C,$B7,Рўйхат!L:L) | L7: =+SUMIF(Рўйхат!$C:$C,$B7,Рўйхат!M:M) | M7: =+SUMIF(Рўйхат!$C:$C,$B7,Рўйхат!N:N) | N7: =+SUMIF(Рўйхат!$C:$C,$B7,Рўйхат!O:O) | O7: =+SUMIF(Рўйхат!$C:$C,$B7,Рўйхат!P:P) | P7: =+SUMIF(Рўйхат!$C:$C,$B7,Рўйхат!Q:Q) | Q7: =+SUMIF(Рўйхат!$C:$C,$B7,Рўйхат!R:R) | R7: =+SUMIF(Рўйхат!$C:$C,$B7,Рўйхат!S:S) | S7: =+SUMIF(Рўйхат!$C:$C,$B7,Рўйхат!T:T) | T7: =+SUMIF(Рўйхат!$C:$C,$B7,Рўйхат!U:U) | U7: =+SUMIF(Рўйхат!$C:$C,$B7,Рўйхат!V:V) | V7: =+SUMIF(Рўйхат!$C:$C,$B7,Рўйхат!W:W) | W7: =+SUMIF(Рўйхат!$C:$C,$B7,Рўйхат!X:X) | X7: =+SUMIF(Рўйхат!$C:$C,$B7,Рўйхат!Y:Y) | Y7: =+SUMIF(Рўйхат!$C:$C,$B7,Рўйхат!Z:Z) | Z7: =+SUMIF(Рўйхат!$C:$C,$B7,Рўйхат!AA:AA) | AA7: =+SUMIF(Рўйхат!$C:$C,$B7,Рўйхат!AB:AB) | AB7: =+SUMIF(Рўйхат!$C:$C,$B7,Рўйхат!AC:AC) | AC7: =+SUMIF(Рўйхат!$C:$C,$B7,Рўйхат!AD:AD) | AD7: =+SUMIF(Рўйхат!$C:$C,$B7,Рўйхат!AE:AE) | AE7: =+SUMIF(Рўйхат!$C:$C,$B7,Рўйхат!AF:AF) | AF7: =+SUMIF(Рўйхат!$C:$C,$B7,Рўйхат!AG:AG) | AG7: =+SUMIF(Рўйхат!$C:$C,$B7,Рўйхат!AH:AH) | AH7: =+SUMIF(Рўйхат!$C:$C,$B7,Рўйхат!AI:AI) | AI7: =+SUMIF(Рўйхат!$C:$C,$B7,Рўйхат!AJ:AJ)
A8: =+A7+1 | B8: Соғлиқни сақлаш вазирлиги | C8: =IF(IFERROR(VLOOKUP(B8,Рўйхат!C:E,2,0),"")="[NULL]","",IFERROR(VLOOKUP(B8,Рўйхат!C:E,2,0),"")) | D8: =IFERROR(VLOOKUP(B8,Рўйхат!C:E,3,0),"") | E8: =+SUMIF(Рўйхат!$C:$C,$B8,Рўйхат!G:G) | F8: =+SUMIF(Рўйхат!$C:$C,$B8,Рўйхат!H:H) | G8: =M8 | H8: =R8+W8+AB8+AG8 | I8: =+SUMIF(Рўйхат!$C:$C,$B8,Рўйхат!J:J) | J8: =+SUMIF(Рўйхат!$C:$C,$B8,Рўйхат!K:K) | K8: =+SUMIF(Рўйхат!$C:$C,$B8,Рўйхат!L:L) | L8: =+SUMIF(Рўйхат!$C:$C,$B8,Рўйхат!M:M) | M8: =+SUMIF(Рўйхат!$C:$C,$B8,Рўйхат!N:N) | N8: =+SUMIF(Рўйхат!$C:$C,$B8,Рўйхат!O:O) | O8: =+SUMIF(Рўйхат!$C:$C,$B8,Рўйхат!P:P) | P8: =+SUMIF(Рўйхат!$C:$C,$B8,Рўйхат!Q:Q) | Q8: =+SUMIF(Рўйхат!$C:$C,$B8,Рўйхат!R:R) | R8: =+SUMIF(Рўйхат!$C:$C,$B8,Рўйхат!S:S) | S8: =+SUMIF(Рўйхат!$C:$C,$B8,Рўйхат!T:T) | T8: =+SUMIF(Рўйхат!$C:$C,$B8,Рўйхат!U:U) | U8: =+SUMIF(Рўйхат!$C:$C,$B8,Рўйхат!V:V) | V8: =+SUMIF(Рўйхат!$C:$C,$B8,Рўйхат!W:W) | W8: =+SUMIF(Рўйхат!$C:$C,$B8,Рўйхат!X:X) | X8: =+SUMIF(Рўйхат!$C:$C,$B8,Рўйхат!Y:Y) | Y8: =+SUMIF(Рўйхат!$C:$C,$B8,Рўйхат!Z:Z) | Z8: =+SUMIF(Рўйхат!$C:$C,$B8,Рўйхат!AA:AA) | AA8: =+SUMIF(Рўйхат!$C:$C,$B8,Рўйхат!AB:AB) | AB8: =+SUMIF(Рўйхат!$C:$C,$B8,Рўйхат!AC:AC) | AC8: =+SUMIF(Рўйхат!$C:$C,$B8,Рўйхат!AD:AD) | AD8: =+SUMIF(Рўйхат!$C:$C,$B8,Рўйхат!AE:AE) | AE8: =+SUMIF(Рўйхат!$C:$C,$B8,Рўйхат!AF:AF) | AF8: =+SUMIF(Рўйхат!$C:$C,$B8,Рўйхат!AG:AG) | AG8: =+SUMIF(Рўйхат!$C:$C,$B8,Рўйхат!AH:AH) | AH8: =+SUMIF(Рўйхат!$C:$C,$B8,Рўйхат!AI:AI) | AI8: =+SUMIF(Рўйхат!$C:$C,$B8,Рўйхат!AJ:AJ)
A9: =+A8+1 | B9: Ғазначилик хизмати қўмитаси | C9: =IF(IFERROR(VLOOKUP(B9,Рўйхат!C:E,2,0),"")="[NULL]","",IFERROR(VLOOKUP(B9,Рўйхат!C:E,2,0),"")) | D9: =IFERROR(VLOOKUP(B9,Рўйхат!C:E,3,0),"") | E9: =+SUMIF(Рўйхат!$C:$C,$B9,Рўйхат!G:G) | F9: =+SUMIF(Рўйхат!$C:$C,$B9,Рўйхат!H:H) | G9: =M9 | H9: =R9+W9+AB9+AG9 | I9: =+SUMIF(Рўйхат!$C:$C,$B9,Рўйхат!J:J) | J9: =+SUMIF(Рўйхат!$C:$C,$B9,Рўйхат!K:K) | K9: =+SUMIF(Рўйхат!$C:$C,$B9,Рўйхат!L:L) | L9: =+SUMIF(Рўйхат!$C:$C,$B9,Рўйхат!M:M) | M9: =+SUMIF(Рўйхат!$C:$C,$B9,Рўйхат!N:N) | N9: =+SUMIF(Рўйхат!$C:$C,$B9,Рўйхат!O:O) | O9: =+SUMIF(Рўйхат!$C:$C,$B9,Рўйхат!P:P) | P9: =+SUMIF(Рўйхат!$C:$C,$B9,Рўйхат!Q:Q) | Q9: =+SUMIF(Рўйхат!$C:$C,$B9,Рўйхат!R:R) | R9: =+SUMIF(Рўйхат!$C:$C,$B9,Рўйхат!S:S) | S9: =+SUMIF(Рўйхат!$C:$C,$B9,Рўйхат!T:T) | T9: =+SUMIF(Рўйхат!$C:$C,$B9,Рўйхат!U:U) | U9: =+SUMIF(Рўйхат!$C:$C,$B9,Рўйхат!V:V) | V9: =+SUMIF(Рўйхат!$C:$C,$B9,Рўйхат!W:W) | W9: =+SUMIF(Рўйхат!$C:$C,$B9,Рўйхат!X:X) | X9: =+SUMIF(Рўйхат!$C:$C,$B9,Рўйхат!Y:Y) | Y9: =+SUMIF(Рўйхат!$C:$C,$B9,Рўйхат!Z:Z) | Z9: =+SUMIF(Рўйхат!$C:$C,$B9,Рўйхат!AA:AA) | AA9: =+SUMIF(Рўйхат!$C:$C,$B9,Рўйхат!AB:AB) | AB9: =+SUMIF(Рўйхат!$C:$C,$B9,Рўйхат!AC:AC) | AC9: =+SUMIF(Рўйхат!$C:$C,$B9,Рўйхат!AD:AD) | AD9: =+SUMIF(Рўйхат!$C:$C,$B9,Рўйхат!AE:AE) | AE9: =+SUMIF(Рўйхат!$C:$C,$B9,Рўйхат!AF:AF) | AF9: =+SUMIF(Рўйхат!$C:$C,$B9,Рўйхат!AG:AG) | AG9: =+SUMIF(Рўйхат!$C:$C,$B9,Рўйхат!AH:AH) | AH9: =+SUMIF(Рўйхат!$C:$C,$B9,Рўйхат!AI:AI) | AI9: =+SUMIF(Рўйхат!$C:$C,$B9,Рўйхат!AJ:AJ)
A10: =+A9+1 | B10: Қурилиш ва уй-жой коммунал хўжалиги вазирлиги | C10: =IF(IFERROR(VLOOKUP(B10,Рўйхат!C:E,2,0),"")="[NULL]","",IFERROR(VLOOKUP(B10,Рўйхат!C:E,2,0),"")) | D10: =IFERROR(VLOOKUP(B10,Рўйхат!C:E,3,0),"") | E10: =+SUMIF(Рўйхат!$C:$C,$B10,Рўйхат!G:G) | F10: =+SUMIF(Рўйхат!$C:$C,$B10,Рўйхат!H:H) | G10: =M10 | H10: =R10+W10+AB10+AG10 | I10: =+SUMIF(Рўйхат!$C:$C,$B10,Рўйхат!J:J) | J10: =+SUMIF(Рўйхат!$C:$C,$B10,Рўйхат!K:K) | K10: =+SUMIF(Рўйхат!$C:$C,$B10,Рўйхат!L:L) | L10: =+SUMIF(Рўйхат!$C:$C,$B10,Рўйхат!M:M) | M10: =+SUMIF(Рўйхат!$C:$C,$B10,Рўйхат!N:N) | N10: =+SUMIF(Рўйхат!$C:$C,$B10,Рўйхат!O:O) | O10: =+SUMIF(Рўйхат!$C:$C,$B10,Рўйхат!P:P) | P10: =+SUMIF(Рўйхат!$C:$C,$B10,Рўйхат!Q:Q) | Q10: =+SUMIF(Рўйхат!$C:$C,$B10,Рўйхат!R:R) | R10: =+SUMIF(Рўйхат!$C:$C,$B10,Рўйхат!S:S) | S10: =+SUMIF(Рўйхат!$C:$C,$B10,Рўйхат!T:T) | T10: =+SUMIF(Рўйхат!$C:$C,$B10,Рўйхат!U:U) | U10: =+SUMIF(Рўйхат!$C:$C,$B10,Рўйхат!V:V) | V10: =+SUMIF(Рўйхат!$C:$C,$B10,Рўйхат!W:W) | W10: =+SUMIF(Рўйхат!$C:$C,$B10,Рўйхат!X:X) | X10: =+SUMIF(Рўйхат!$C:$C,$B10,Рўйхат!Y:Y) | Y10: =+SUMIF(Рўйхат!$C:$C,$B10,Рўйхат!Z:Z) | Z10: =+SUMIF(Рўйхат!$C:$C,$B10,Рўйхат!AA:AA) | AA10: =+SUMIF(Рўйхат!$C:$C,$B10,Рўйхат!AB:AB) | AB10: =+SUMIF(Рўйхат!$C:$C,$B10,Рўйхат!AC:AC) | AC10: =+SUMIF(Рўйхат!$C:$C,$B10,Рўйхат!AD:AD) | AD10: =+SUMIF(Рўйхат!$C:$C,$B10,Рўйхат!AE:AE) | AE10: =+SUMIF(Рўйхат!$C:$C,$B10,Рўйхат!AF:AF) | AF10: =+SUMIF(Рўйхат!$C:$C,$B10,Рўйхат!AG:AG) | AG10: =+SUMIF(Рўйхат!$C:$C,$B10,Рўйхат!AH:AH) | AH10: =+SUMIF(Рўйхат!$C:$C,$B10,Рўйхат!AI:AI) | AI10: =+SUMIF(Рўйхат!$C:$C,$B10,Рўйхат!AJ:AJ)
A11: =+A10+1 | B11: Олий таълим, фан ва инновациялар вазирлиги | C11: =IF(IFERROR(VLOOKUP(B11,Рўйхат!C:E,2,0),"")="[NULL]","",IFERROR(VLOOKUP(B11,Рўйхат!C:E,2,0),"")) | D11: =IFERROR(VLOOKUP(B11,Рўйхат!C:E,3,0),"") | E11: =+SUMIF(Рўйхат!$C:$C,$B11,Рўйхат!G:G) | F11: =+SUMIF(Рўйхат!$C:$C,$B11,Рўйхат!H:H) | G11: =M11 | H11: =R11+W11+AB11+AG11 | I11: =+SUMIF(Рўйхат!$C:$C,$B11,Рўйхат!J:J) | J11: =+SUMIF(Рўйхат!$C:$C,$B11,Рўйхат!K:K) | K11: =+SUMIF(Рўйхат!$C:$C,$B11,Рўйхат!L:L) | L11: =+SUMIF(Рўйхат!$C:$C,$B11,Рўйхат!M:M) | M11: =+SUMIF(Рўйхат!$C:$C,$B11,Рўйхат!N:N) | N11: =+SUMIF(Рўйхат!$C:$C,$B11,Рўйхат!O:O) | O11: =+SUMIF(Рўйхат!$C:$C,$B11,Рўйхат!P:P) | P11: =+SUMIF(Рўйхат!$C:$C,$B11,Рўйхат!Q:Q) | Q11: =+SUMIF(Рўйхат!$C:$C,$B11,Рўйхат!R:R) | R11: =+SUMIF(Рўйхат!$C:$C,$B11,Рўйхат!S:S) | S11: =+SUMIF(Рўйхат!$C:$C,$B11,Рўйхат!T:T) | T11: =+SUMIF(Рўйхат!$C:$C,$B11,Рўйхат!U:U) | U11: =+SUMIF(Рўйхат!$C:$C,$B11,Рўйхат!V:V) | V11: =+SUMIF(Рўйхат!$C:$C,$B11,Рўйхат!W:W) | W11: =+SUMIF(Рўйхат!$C:$C,$B11,Рўйхат!X:X) | X11: =+SUMIF(Рўйхат!$C:$C,$B11,Рўйхат!Y:Y) | Y11: =+SUMIF(Рўйхат!$C:$C,$B11,Рўйхат!Z:Z) | Z11: =+SUMIF(Рўйхат!$C:$C,$B11,Рўйхат!AA:AA) | AA11: =+SUMIF(Рўйхат!$C:$C,$B11,Рўйхат!AB:AB) | AB11: =+SUMIF(Рўйхат!$C:$C,$B11,Рўйхат!AC:AC) | AC11: =+SUMIF(Рўйхат!$C:$C,$B11,Рўйхат!AD:AD) | AD11: =+SUMIF(Рўйхат!$C:$C,$B11,Рўйхат!AE:AE) | AE11: =+SUMIF(Рўйхат!$C:$C,$B11,Рўйхат!AF:AF) | AF11: =+SUMIF(Рўйхат!$C:$C,$B11,Рўйхат!AG:AG) | AG11: =+SUMIF(Рўйхат!$C:$C,$B11,Рўйхат!AH:AH) | AH11: =+SUMIF(Рўйхат!$C:$C,$B11,Рўйхат!AI:AI) | AI11: =+SUMIF(Рўйхат!$C:$C,$B11,Рўйхат!AJ:AJ)
A12: =+A11+1 | B12: “Ўзбекнефтгаз” АЖ | C12: =IF(IFERROR(VLOOKUP(B12,Рўйхат!C:E,2,0),"")="[NULL]","",IFERROR(VLOOKUP(B12,Рўйхат!C:E,2,0),"")) | D12: =IFERROR(VLOOKUP(B12,Рўйхат!C:E,3,0),"") | E12: =+SUMIF(Рўйхат!$C:$C,$B12,Рўйхат!G:G) | F12: =+SUMIF(Рўйхат!$C:$C,$B12,Рўйхат!H:H) | G12: =M12 | H12: =R12+W12+AB12+AG12 | I12: =+SUMIF(Рўйхат!$C:$C,$B12,Рўйхат!J:J) | J12: =+SUMIF(Рўйхат!$C:$C,$B12,Рўйхат!K:K) | K12: =+SUMIF(Рўйхат!$C:$C,$B12,Рўйхат!L:L) | L12: =+SUMIF(Рўйхат!$C:$C,$B12,Рўйхат!M:M) | M12: =+SUMIF(Рўйхат!$C:$C,$B12,Рўйхат!N:N) | N12: =+SUMIF(Рўйхат!$C:$C,$B12,Рўйхат!O:O) | O12: =+SUMIF(Рўйхат!$C:$C,$B12,Рўйхат!P:P) | P12: =+SUMIF(Рўйхат!$C:$C,$B12,Рўйхат!Q:Q) | Q12: =+SUMIF(Рўйхат!$C:$C,$B12,Рўйхат!R:R) | R12: =+SUMIF(Рўйхат!$C:$C,$B12,Рўйхат!S:S) | S12: =+SUMIF(Рўйхат!$C:$C,$B12,Рўйхат!T:T) | T12: =+SUMIF(Рўйхат!$C:$C,$B12,Рўйхат!U:U) | U12: =+SUMIF(Рўйхат!$C:$C,$B12,Рўйхат!V:V) | V12: =+SUMIF(Рўйхат!$C:$C,$B12,Рўйхат!W:W) | W12: =+SUMIF(Рўйхат!$C:$C,$B12,Рўйхат!X:X) | X12: =+SUMIF(Рўйхат!$C:$C,$B12,Рўйхат!Y:Y) | Y12: =+SUMIF(Рўйхат!$C:$C,$B12,Рўйхат!Z:Z) | Z12: =+SUMIF(Рўйхат!$C:$C,$B12,Рўйхат!AA:AA) | AA12: =+SUMIF(Рўйхат!$C:$C,$B12,Рўйхат!AB:AB) | AB12: =+SUMIF(Рўйхат!$C:$C,$B12,Рўйхат!AC:AC) | AC12: =+SUMIF(Рўйхат!$C:$C,$B12,Рўйхат!AD:AD) | AD12: =+SUMIF(Рўйхат!$C:$C,$B12,Рўйхат!AE:AE) | AE12: =+SUMIF(Рўйхат!$C:$C,$B12,Рўйхат!AF:AF) | AF12: =+SUMIF(Рўйхат!$C:$C,$B12,Рўйхат!AG:AG) | AG12: =+SUMIF(Рўйхат!$C:$C,$B12,Рўйхат!AH:AH) | AH12: =+SUMIF(Рўйхат!$C:$C,$B12,Рўйхат!AI:AI) | AI12: =+SUMIF(Рўйхат!$C:$C,$B12,Рўйхат!AJ:AJ)
A13: =+A12+1 | B13: АТ Халқ банк | C13: =IF(IFERROR(VLOOKUP(B13,Рўйхат!C:E,2,0),"")="[NULL]","",IFERROR(VLOOKUP(B13,Рўйхат!C:E,2,0),"")) | D13: =IFERROR(VLOOKUP(B13,Рўйхат!C:E,3,0),"") | E13: =+SUMIF(Рўйхат!$C:$C,$B13,Рўйхат!G:G) | F13: =+SUMIF(Рўйхат!$C:$C,$B13,Рўйхат!H:H) | G13: =M13 | H13: =R13+W13+AB13+AG13 | I13: =+SUMIF(Рўйхат!$C:$C,$B13,Рўйхат!J:J) | J13: =+SUMIF(Рўйхат!$C:$C,$B13,Рўйхат!K:K) | K13: =+SUMIF(Рўйхат!$C:$C,$B13,Рўйхат!L:L) | L13: =+SUMIF(Рўйхат!$C:$C,$B13,Рўйхат!M:M) | M13: =+SUMIF(Рўйхат!$C:$C,$B13,Рўйхат!N:N) | N13: =+SUMIF(Рўйхат!$C:$C,$B13,Рўйхат!O:O) | O13: =+SUMIF(Рўйхат!$C:$C,$B13,Рўйхат!P:P) | P13: =+SUMIF(Рўйхат!$C:$C,$B13,Рўйхат!Q:Q) | Q13: =+SUMIF(Рўйхат!$C:$C,$B13,Рўйхат!R:R) | R13: =+SUMIF(Рўйхат!$C:$C,$B13,Рўйхат!S:S) | S13: =+SUMIF(Рўйхат!$C:$C,$B13,Рўйхат!T:T) | T13: =+SUMIF(Рўйхат!$C:$C,$B13,Рўйхат!U:U) | U13: =+SUMIF(Рўйхат!$C:$C,$B13,Рўйхат!V:V) | V13: =+SUMIF(Рўйхат!$C:$C,$B13,Рўйхат!W:W) | W13: =+SUMIF(Рўйхат!$C:$C,$B13,Рўйхат!X:X) | X13: =+SUMIF(Рўйхат!$C:$C,$B13,Рўйхат!Y:Y) | Y13: =+SUMIF(Рўйхат!$C:$C,$B13,Рўйхат!Z:Z) | Z13: =+SUMIF(Рўйхат!$C:$C,$B13,Рўйхат!AA:AA) | AA13: =+SUMIF(Рўйхат!$C:$C,$B13,Рўйхат!AB:AB) | AB13: =+SUMIF(Рўйхат!$C:$C,$B13,Рўйхат!AC:AC) | AC13: =+SUMIF(Рўйхат!$C:$C,$B13,Рўйхат!AD:AD) | AD13: =+SUMIF(Рўйхат!$C:$C,$B13,Рўйхат!AE:AE) | AE13: =+SUMIF(Рўйхат!$C:$C,$B13,Рўйхат!AF:AF) | AF13: =+SUMIF(Рўйхат!$C:$C,$B13,Рўйхат!AG:AG) | AG13: =+SUMIF(Рўйхат!$C:$C,$B13,Рўйхат!AH:AH) | AH13: =+SUMIF(Рўйхат!$C:$C,$B13,Рўйхат!AI:AI) | AI13: =+SUMIF(Рўйхат!$C:$C,$B13,Рўйхат!AJ:AJ)
A14: =+A13+1 | B14: Маданият вазирлиги | C14: =IF(IFERROR(VLOOKUP(B14,Рўйхат!C:E,2,0),"")="[NULL]","",IFERROR(VLOOKUP(B14,Рўйхат!C:E,2,0),"")) | D14: =IFERROR(VLOOKUP(B14,Рўйхат!C:E,3,0),"") | E14: =+SUMIF(Рўйхат!$C:$C,$B14,Рўйхат!G:G) | F14: =+SUMIF(Рўйхат!$C:$C,$B14,Рўйхат!H:H) | G14: =M14 | H14: =R14+W14+AB14+AG14 | I14: =+SUMIF(Рўйхат!$C:$C,$B14,Рўйхат!J:J) | J14: =+SUMIF(Рўйхат!$C:$C,$B14,Рўйхат!K:K) | K14: =+SUMIF(Рўйхат!$C:$C,$B14,Рўйхат!L:L) | L14: =+SUMIF(Рўйхат!$C:$C,$B14,Рўйхат!M:M) | M14: =+SUMIF(Рўйхат!$C:$C,$B14,Рўйхат!N:N) | N14: =+SUMIF(Рўйхат!$C:$C,$B14,Рўйхат!O:O) | O14: =+SUMIF(Рўйхат!$C:$C,$B14,Рўйхат!P:P) | P14: =+SUMIF(Рўйхат!$C:$C,$B14,Рўйхат!Q:Q) | Q14: =+SUMIF(Рўйхат!$C:$C,$B14,Рўйхат!R:R) | R14: =+SUMIF(Рўйхат!$C:$C,$B14,Рўйхат!S:S) | S14: =+SUMIF(Рўйхат!$C:$C,$B14,Рўйхат!T:T) | T14: =+SUMIF(Рўйхат!$C:$C,$B14,Рўйхат!U:U) | U14: =+SUMIF(Рўйхат!$C:$C,$B14,Рўйхат!V:V) | V14: =+SUMIF(Рўйхат!$C:$C,$B14,Рўйхат!W:W) | W14: =+SUMIF(Рўйхат!$C:$C,$B14,Рўйхат!X:X) | X14: =+SUMIF(Рўйхат!$C:$C,$B14,Рўйхат!Y:Y) | Y14: =+SUMIF(Рўйхат!$C:$C,$B14,Рўйхат!Z:Z) | Z14: =+SUMIF(Рўйхат!$C:$C,$B14,Рўйхат!AA:AA) | AA14: =+SUMIF(Рўйхат!$C:$C,$B14,Рўйхат!AB:AB) | AB14: =+SUMIF(Рўйхат!$C:$C,$B14,Рўйхат!AC:AC) | AC14: =+SUMIF(Рўйхат!$C:$C,$B14,Рўйхат!AD:AD) | AD14: =+SUMIF(Рўйхат!$C:$C,$B14,Рўйхат!AE:AE) | AE14: =+SUMIF(Рўйхат!$C:$C,$B14,Рўйхат!AF:AF) | AF14: =+SUMIF(Рўйхат!$C:$C,$B14,Рўйхат!AG:AG) | AG14: =+SUMIF(Рўйхат!$C:$C,$B14,Рўйхат!AH:AH) | AH14: =+SUMIF(Рўйхат!$C:$C,$B14,Рўйхат!AI:AI) | AI14: =+SUMIF(Рўйхат!$C:$C,$B14,Рўйхат!AJ:AJ)
A15: =+A14+1 | B15: Ижтимоий ҳимоя миллий агентлиги | C15: =IF(IFERROR(VLOOKUP(B15,Рўйхат!C:E,2,0),"")="[NULL]","",IFERROR(VLOOKUP(B15,Рўйхат!C:E,2,0),"")) | D15: =IFERROR(VLOOKUP(B15,Рўйхат!C:E,3,0),"") | E15: =+SUMIF(Рўйхат!$C:$C,$B15,Рўйхат!G:G) | F15: =+SUMIF(Рўйхат!$C:$C,$B15,Рўйхат!H:H) | G15: =M15 | H15: =R15+W15+AB15+AG15 | I15: =+SUMIF(Рўйхат!$C:$C,$B15,Рўйхат!J:J) | J15: =+SUMIF(Рўйхат!$C:$C,$B15,Рўйхат!K:K) | K15: =+SUMIF(Рўйхат!$C:$C,$B15,Рўйхат!L:L) | L15: =+SUMIF(Рўйхат!$C:$C,$B15,Рўйхат!M:M) | M15: =+SUMIF(Рўйхат!$C:$C,$B15,Рўйхат!N:N) | N15: =+SUMIF(Рўйхат!$C:$C,$B15,Рўйхат!O:O) | O15: =+SUMIF(Рўйхат!$C:$C,$B15,Рўйхат!P:P) | P15: =+SUMIF(Рўйхат!$C:$C,$B15,Рўйхат!Q:Q) | Q15: =+SUMIF(Рўйхат!$C:$C,$B15,Рўйхат!R:R) | R15: =+SUMIF(Рўйхат!$C:$C,$B15,Рўйхат!S:S) | S15: =+SUMIF(Рўйхат!$C:$C,$B15,Рўйхат!T:T) | T15: =+SUMIF(Рўйхат!$C:$C,$B15,Рўйхат!U:U) | U15: =+SUMIF(Рўйхат!$C:$C,$B15,Рўйхат!V:V) | V15: =+SUMIF(Рўйхат!$C:$C,$B15,Рўйхат!W:W) | W15: =+SUMIF(Рўйхат!$C:$C,$B15,Рўйхат!X:X) | X15: =+SUMIF(Рўйхат!$C:$C,$B15,Рўйхат!Y:Y) | Y15: =+SUMIF(Рўйхат!$C:$C,$B15,Рўйхат!Z:Z) | Z15: =+SUMIF(Рўйхат!$C:$C,$B15,Рўйхат!AA:AA) | AA15: =+SUMIF(Рўйхат!$C:$C,$B15,Рўйхат!AB:AB) | AB15: =+SUMIF(Рўйхат!$C:$C,$B15,Рўйхат!AC:AC) | AC15: =+SUMIF(Рўйхат!$C:$C,$B15,Рўйхат!AD:AD) | AD15: =+SUMIF(Рўйхат!$C:$C,$B15,Рўйхат!AE:AE) | AE15: =+SUMIF(Рўйхат!$C:$C,$B15,Рўйхат!AF:AF) | AF15: =+SUMIF(Рўйхат!$C:$C,$B15,Рўйхат!AG:AG) | AG15: =+SUMIF(Рўйхат!$C:$C,$B15,Рўйхат!AH:AH) | AH15: =+SUMIF(Рўйхат!$C:$C,$B15,Рўйхат!AI:AI) | AI15: =+SUMIF(Рўйхат!$C:$C,$B15,Рўйхат!AJ:AJ)
A16: =+A15+1 | B16: Қишлоқ хўжалиги вазирлиги | C16: =IF(IFERROR(VLOOKUP(B16,Рўйхат!C:E,2,0),"")="[NULL]","",IFERROR(VLOOKUP(B16,Рўйхат!C:E,2,0),"")) | D16: =IFERROR(VLOOKUP(B16,Рўйхат!C:E,3,0),"") | E16: =+SUMIF(Рўйхат!$C:$C,$B16,Рўйхат!G:G) | F16: =+SUMIF(Рўйхат!$C:$C,$B16,Рўйхат!H:H) | G16: =M16 | H16: =R16+W16+AB16+AG16 | I16: =+SUMIF(Рўйхат!$C:$C,$B16,Рўйхат!J:J) | J16: =+SUMIF(Рўйхат!$C:$C,$B16,Рўйхат!K:K) | K16: =+SUMIF(Рўйхат!$C:$C,$B16,Рўйхат!L:L) | L16: =+SUMIF(Рўйхат!$C:$C,$B16,Рўйхат!M:M) | M16: =+SUMIF(Рўйхат!$C:$C,$B16,Рўйхат!N:N) | N16: =+SUMIF(Рўйхат!$C:$C,$B16,Рўйхат!O:O) | O16: =+SUMIF(Рўйхат!$C:$C,$B16,Рўйхат!P:P) | P16: =+SUMIF(Рўйхат!$C:$C,$B16,Рўйхат!Q:Q) | Q16: =+SUMIF(Рўйхат!$C:$C,$B16,Рўйхат!R:R) | R16: =+SUMIF(Рўйхат!$C:$C,$B16,Рўйхат!S:S) | S16: =+SUMIF(Рўйхат!$C:$C,$B16,Рўйхат!T:T) | T16: =+SUMIF(Рўйхат!$C:$C,$B16,Рўйхат!U:U) | U16: =+SUMIF(Рўйхат!$C:$C,$B16,Рўйхат!V:V) | V16: =+SUMIF(Рўйхат!$C:$C,$B16,Рўйхат!W:W) | W16: =+SUMIF(Рўйхат!$C:$C,$B16,Рўйхат!X:X) | X16: =+SUMIF(Рўйхат!$C:$C,$B16,Рўйхат!Y:Y) | Y16: =+SUMIF(Рўйхат!$C:$C,$B16,Рўйхат!Z:Z) | Z16: =+SUMIF(Рўйхат!$C:$C,$B16,Рўйхат!AA:AA) | AA16: =+SUMIF(Рўйхат!$C:$C,$B16,Рўйхат!AB:AB) | AB16: =+SUMIF(Рўйхат!$C:$C,$B16,Рўйхат!AC:AC) | AC16: =+SUMIF(Рўйхат!$C:$C,$B16,Рўйхат!AD:AD) | AD16: =+SUMIF(Рўйхат!$C:$C,$B16,Рўйхат!AE:AE) | AE16: =+SUMIF(Рўйхат!$C:$C,$B16,Рўйхат!AF:AF) | AF16: =+SUMIF(Рўйхат!$C:$C,$B16,Рўйхат!AG:AG) | AG16: =+SUMIF(Рўйхат!$C:$C,$B16,Рўйхат!AH:AH) | AH16: =+SUMIF(Рўйхат!$C:$C,$B16,Рўйхат!AI:AI) | AI16: =+SUMIF(Рўйхат!$C:$C,$B16,Рўйхат!AJ:AJ)
A17: =+A16+1 | B17: Сув хўжалиги вазирлиги | C17: =IF(IFERROR(VLOOKUP(B17,Рўйхат!C:E,2,0),"")="[NULL]","",IFERROR(VLOOKUP(B17,Рўйхат!C:E,2,0),"")) | D17: =IFERROR(VLOOKUP(B17,Рўйхат!C:E,3,0),"") | E17: =+SUMIF(Рўйхат!$C:$C,$B17,Рўйхат!G:G) | F17: =+SUMIF(Рўйхат!$C:$C,$B17,Рўйхат!H:H) | G17: =M17 | H17: =R17+W17+AB17+AG17 | I17: =+SUMIF(Рўйхат!$C:$C,$B17,Рўйхат!J:J) | J17: =+SUMIF(Рўйхат!$C:$C,$B17,Рўйхат!K:K) | K17: =+SUMIF(Рўйхат!$C:$C,$B17,Рўйхат!L:L) | L17: =+SUMIF(Рўйхат!$C:$C,$B17,Рўйхат!M:M) | M17: =+SUMIF(Рўйхат!$C:$C,$B17,Рўйхат!N:N) | N17: =+SUMIF(Рўйхат!$C:$C,$B17,Рўйхат!O:O) | O17: =+SUMIF(Рўйхат!$C:$C,$B17,Рўйхат!P:P) | P17: =+SUMIF(Рўйхат!$C:$C,$B17,Рўйхат!Q:Q) | Q17: =+SUMIF(Рўйхат!$C:$C,$B17,Рўйхат!R:R) | R17: =+SUMIF(Рўйхат!$C:$C,$B17,Рўйхат!S:S) | S17: =+SUMIF(Рўйхат!$C:$C,$B17,Рўйхат!T:T) | T17: =+SUMIF(Рўйхат!$C:$C,$B17,Рўйхат!U:U) | U17: =+SUMIF(Рўйхат!$C:$C,$B17,Рўйхат!V:V) | V17: =+SUMIF(Рўйхат!$C:$C,$B17,Рўйхат!W:W) | W17: =+SUMIF(Рўйхат!$C:$C,$B17,Рўйхат!X:X) | X17: =+SUMIF(Рўйхат!$C:$C,$B17,Рўйхат!Y:Y) | Y17: =+SUMIF(Рўйхат!$C:$C,$B17,Рўйхат!Z:Z) | Z17: =+SUMIF(Рўйхат!$C:$C,$B17,Рўйхат!AA:AA) | AA17: =+SUMIF(Рўйхат!$C:$C,$B17,Рўйхат!AB:AB) | AB17: =+SUMIF(Рўйхат!$C:$C,$B17,Рўйхат!AC:AC) | AC17: =+SUMIF(Рўйхат!$C:$C,$B17,Рўйхат!AD:AD) | AD17: =+SUMIF(Рўйхат!$C:$C,$B17,Рўйхат!AE:AE) | AE17: =+SUMIF(Рўйхат!$C:$C,$B17,Рўйхат!AF:AF) | AF17: =+SUMIF(Рўйхат!$C:$C,$B17,Рўйхат!AG:AG) | AG17: =+SUMIF(Рўйхат!$C:$C,$B17,Рўйхат!AH:AH) | AH17: =+SUMIF(Рўйхат!$C:$C,$B17,Рўйхат!AI:AI) | AI17: =+SUMIF(Рўйхат!$C:$C,$B17,Рўйхат!AJ:AJ)
A18: =+A17+1 | B18: Камбағалликни қисқартириш ва бандлик вазирлиги | C18: =IF(IFERROR(VLOOKUP(B18,Рўйхат!C:E,2,0),"")="[NULL]","",IFERROR(VLOOKUP(B18,Рўйхат!C:E,2,0),"")) | D18: =IFERROR(VLOOKUP(B18,Рўйхат!C:E,3,0),"") | E18: =+SUMIF(Рўйхат!$C:$C,$B18,Рўйхат!G:G) | F18: =+SUMIF(Рўйхат!$C:$C,$B18,Рўйхат!H:H) | G18: =M18 | H18: =R18+W18+AB18+AG18 | I18: =+SUMIF(Рўйхат!$C:$C,$B18,Рўйхат!J:J) | J18: =+SUMIF(Рўйхат!$C:$C,$B18,Рўйхат!K:K) | K18: =+SUMIF(Рўйхат!$C:$C,$B18,Рўйхат!L:L) | L18: =+SUMIF(Рўйхат!$C:$C,$B18,Рўйхат!M:M) | M18: =+SUMIF(Рўйхат!$C:$C,$B18,Рўйхат!N:N) | N18: =+SUMIF(Рўйхат!$C:$C,$B18,Рўйхат!O:O) | O18: =+SUMIF(Рўйхат!$C:$C,$B18,Рўйхат!P:P) | P18: =+SUMIF(Рўйхат!$C:$C,$B18,Рўйхат!Q:Q) | Q18: =+SUMIF(Рўйхат!$C:$C,$B18,Рўйхат!R:R) | R18: =+SUMIF(Рўйхат!$C:$C,$B18,Рўйхат!S:S) | S18: =+SUMIF(Рўйхат!$C:$C,$B18,Рўйхат!T:T) | T18: =+SUMIF(Рўйхат!$C:$C,$B18,Рўйхат!U:U) | U18: =+SUMIF(Рўйхат!$C:$C,$B18,Рўйхат!V:V) | V18: =+SUMIF(Рўйхат!$C:$C,$B18,Рўйхат!W:W) | W18: =+SUMIF(Рўйхат!$C:$C,$B18,Рўйхат!X:X) | X18: =+SUMIF(Рўйхат!$C:$C,$B18,Рўйхат!Y:Y) | Y18: =+SUMIF(Рўйхат!$C:$C,$B18,Рўйхат!Z:Z) | Z18: =+SUMIF(Рўйхат!$C:$C,$B18,Рўйхат!AA:AA) | AA18: =+SUMIF(Рўйхат!$C:$C,$B18,Рўйхат!AB:AB) | AB18: =+SUMIF(Рўйхат!$C:$C,$B18,Рўйхат!AC:AC) | AC18: =+SUMIF(Рўйхат!$C:$C,$B18,Рўйхат!AD:AD) | AD18: =+SUMIF(Рўйхат!$C:$C,$B18,Рўйхат!AE:AE) | AE18: =+SUMIF(Рўйхат!$C:$C,$B18,Рўйхат!AF:AF) | AF18: =+SUMIF(Рўйхат!$C:$C,$B18,Рўйхат!AG:AG) | AG18: =+SUMIF(Рўйхат!$C:$C,$B18,Рўйхат!AH:AH) | AH18: =+SUMIF(Рўйхат!$C:$C,$B18,Рўйхат!AI:AI) | AI18: =+SUMIF(Рўйхат!$C:$C,$B18,Рўйхат!AJ:AJ)
... A24: =+A23+1 | B24: Тошкент вилояти ҳокимлиги | C24: =IF(IFERROR(VLOOKUP(B24,Рўйхат!C:E,2,0),"")="[NULL]","",IFERROR(VLOOKUP(B24,Рўйхат!C:E,2,0),"")) | D24: =IFERROR(VLOOKUP(B24,Рўйхат!C:E,3,0),"") | E24: =+SUMIF(Рўйхат!$C:$C,$B24,Рўйхат!G:G) | F24: =+SUMIF(Рўйхат!$C:$C,$B24,Рўйхат!H:H) | G24: =M24 | H24: =R24+W24+AB24+AG24 | I24: =+SUMIF(Рўйхат!$C:$C,$B24,Рўйхат!J:J) | J24: =+SUMIF(Рўйхат!$C:$C,$B24,Рўйхат!K:K) | K24: =+SUMIF(Рўйхат!$C:$C,$B24,Рўйхат!L:L) | L24: =+SUMIF(Рўйхат!$C:$C,$B24,Рўйхат!M:M) | M24: =+SUMIF(Рўйхат!$C:$C,$B24,Рўйхат!N:N) | N24: =+SUMIF(Рўйхат!$C:$C,$B24,Рўйхат!O:O) | O24: =+SUMIF(Рўйхат!$C:$C,$B24,Рўйхат!P:P) | P24: =+SUMIF(Рўйхат!$C:$C,$B24,Рўйхат!Q:Q) | Q24: =+SUMIF(Рўйхат!$C:$C,$B24,Рўйхат!R:R) | R24: =+SUMIF(Рўйхат!$C:$C,$B24,Рўйхат!S:S) | S24: =+SUMIF(Рўйхат!$C:$C,$B24,Рўйхат!T:T) | T24: =+SUMIF(Рўйхат!$C:$C,$B24,Рўйхат!U:U) | U24: =+SUMIF(Рўйхат!$C:$C,$B24,Рўйхат!V:V) | V24: =+SUMIF(Рўйхат!$C:$C,$B24,Рўйхат!W:W) | W24: =+SUMIF(Рўйхат!$C:$C,$B24,Рўйхат!X:X) | X24: =+SUMIF(Рўйхат!$C:$C,$B24,Рўйхат!Y:Y) | Y24: =+SUMIF(Рўйхат!$C:$C,$B24,Рўйхат!Z:Z) | Z24: =+SUMIF(Рўйхат!$C:$C,$B24,Рўйхат!AA:AA) | AA24: =+SUMIF(Рўйхат!$C:$C,$B24,Рўйхат!AB:AB) | AB24: =+SUMIF(Рўйхат!$C:$C,$B24,Рўйхат!AC:AC) | AC24: =+SUMIF(Рўйхат!$C:$C,$B24,Рўйхат!AD:AD) | AD24: =+SUMIF(Рўйхат!$C:$C,$B24,Рўйхат!AE:AE) | AE24: =+SUMIF(Рўйхат!$C:$C,$B24,Рўйхат!AF:AF) | AF24: =+SUMIF(Рўйхат!$C:$C,$B24,Рўйхат!AG:AG) | AG24: =+SUMIF(Рўйхат!$C:$C,$B24,Рўйхат!AH:AH) | AH24: =+SUMIF(Рўйхат!$C:$C,$B24,Рўйхат!AI:AI) | AI24: =+SUMIF(Рўйхат!$C:$C,$B24,Рўйхат!AJ:AJ)
A25: =+A24+1 | B25: Қурилиш ва уй-жой коммунал хўжалиги соҳасида назорат қилиш инспекцияси | C25: =IF(IFERROR(VLOOKUP(B25,Рўйхат!C:E,2,0),"")="[NULL]","",IFERROR(VLOOKUP(B25,Рўйхат!C:E,2,0),"")) | E25: =+SUMIF(Рўйхат!$C:$C,$B25,Рўйхат!G:G) | F25: =+SUMIF(Рўйхат!$C:$C,$B25,Рўйхат!H:H) | G25: =M25 | H25: =R25+W25+AB25+AG25 | I25: =+SUMIF(Рўйхат!$C:$C,$B25,Рўйхат!J:J) | J25: =+SUMIF(Рўйхат!$C:$C,$B25,Рўйхат!K:K) | K25: =+SUMIF(Рўйхат!$C:$C,$B25,Рўйхат!L:L) | L25: =+SUMIF(Рўйхат!$C:$C,$B25,Рўйхат!M:M) | M25: =+SUMIF(Рўйхат!$C:$C,$B25,Рўйхат!N:N) | N25: =+SUMIF(Рўйхат!$C:$C,$B25,Рўйхат!O:O) | O25: =+SUMIF(Рўйхат!$C:$C,$B25,Рўйхат!P:P) | P25: =+SUMIF(Рўйхат!$C:$C,$B25,Рўйхат!Q:Q) | Q25: =+SUMIF(Рўйхат!$C:$C,$B25,Рўйхат!R:R) | R25: =+SUMIF(Рўйхат!$C:$C,$B25,Рўйхат!S:S) | S25: =+SUMIF(Рўйхат!$C:$C,$B25,Рўйхат!T:T) | T25: =+SUMIF(Рўйхат!$C:$C,$B25,Рўйхат!U:U) | U25: =+SUMIF(Рўйхат!$C:$C,$B25,Рўйхат!V:V) | V25: =+SUMIF(Рўйхат!$C:$C,$B25,Рўйхат!W:W) | W25: =+SUMIF(Рўйхат!$C:$C,$B25,Рўйхат!X:X) | X25: =+SUMIF(Рўйхат!$C:$C,$B25,Рўйхат!Y:Y) | Y25: =+SUMIF(Рўйхат!$C:$C,$B25,Рўйхат!Z:Z) | Z25: =+SUMIF(Рўйхат!$C:$C,$B25,Рўйхат!AA:AA) | AA25: =+SUMIF(Рўйхат!$C:$C,$B25,Рўйхат!AB:AB) | AB25: =+SUMIF(Рўйхат!$C:$C,$B25,Рўйхат!AC:AC) | AC25: =+SUMIF(Рўйхат!$C:$C,$B25,Рўйхат!AD:AD) | AD25: =+SUMIF(Рўйхат!$C:$C,$B25,Рўйхат!AE:AE) | AE25: =+SUMIF(Рўйхат!$C:$C,$B25,Рўйхат!AF:AF) | AF25: =+SUMIF(Рўйхат!$C:$C,$B25,Рўйхат!AG:AG) | AG25: =+SUMIF(Рўйхат!$C:$C,$B25,Рўйхат!AH:AH) | AH25: =+SUMIF(Рўйхат!$C:$C,$B25,Рўйхат!AI:AI) | AI25: =+SUMIF(Рўйхат!$C:$C,$B25,Рўйхат!AJ:AJ)
A26: =+A25+1 | B26: Адлия вазирлиги | C26: =IF(IFERROR(VLOOKUP(B26,Рўйхат!C:E,2,0),"")="[NULL]","",IFERROR(VLOOKUP(B26,Рўйхат!C:E,2,0),"")) | D26: =IFERROR(VLOOKUP(B26,Рўйхат!C:E,3,0),"") | E26: =+SUMIF(Рўйхат!$C:$C,$B26,Рўйхат!G:G) | F26: =+SUMIF(Рўйхат!$C:$C,$B26,Рўйхат!H:H) | G26: =M26 | H26: =R26+W26+AB26+AG26 | I26: =+SUMIF(Рўйхат!$C:$C,$B26,Рўйхат!J:J) | J26: =+SUMIF(Рўйхат!$C:$C,$B26,Рўйхат!K:K) | K26: =+SUMIF(Рўйхат!$C:$C,$B26,Рўйхат!L:L) | L26: =+SUMIF(Рўйхат!$C:$C,$B26,Рўйхат!M:M) | M26: =+SUMIF(Рўйхат!$C:$C,$B26,Рўйхат!N:N) | N26: =+SUMIF(Рўйхат!$C:$C,$B26,Рўйхат!O:O) | O26: =+SUMIF(Рўйхат!$C:$C,$B26,Рўйхат!P:P) | P26: =+SUMIF(Рўйхат!$C:$C,$B26,Рўйхат!Q:Q) | Q26: =+SUMIF(Рўйхат!$C:$C,$B26,Рўйхат!R:R) | R26: =+SUMIF(Рўйхат!$C:$C,$B26,Рўйхат!S:S) | S26: =+SUMIF(Рўйхат!$C:$C,$B26,Рўйхат!T:T) | T26: =+SUMIF(Рўйхат!$C:$C,$B26,Рўйхат!U:U) | U26: =+SUMIF(Рўйхат!$C:$C,$B26,Рўйхат!V:V) | V26: =+SUMIF(Рўйхат!$C:$C,$B26,Рўйхат!W:W) | W26: =+SUMIF(Рўйхат!$C:$C,$B26,Рўйхат!X:X) | X26: =+SUMIF(Рўйхат!$C:$C,$B26,Рўйхат!Y:Y) | Y26: =+SUMIF(Рўйхат!$C:$C,$B26,Рўйхат!Z:Z) | Z26: =+SUMIF(Рўйхат!$C:$C,$B26,Рўйхат!AA:AA) | AA26: =+SUMIF(Рўйхат!$C:$C,$B26,Рўйхат!AB:AB) | AB26: =+SUMIF(Рўйхат!$C:$C,$B26,Рўйхат!AC:AC) | AC26: =+SUMIF(Рўйхат!$C:$C,$B26,Рўйхат!AD:AD) | AD26: =+SUMIF(Рўйхат!$C:$C,$B26,Рўйхат!AE:AE) | AE26: =+SUMIF(Рўйхат!$C:$C,$B26,Рўйхат!AF:AF) | AF26: =+SUMIF(Рўйхат!$C:$C,$B26,Рўйхат!AG:AG) | AG26: =+SUMIF(Рўйхат!$C:$C,$B26,Рўйхат!AH:AH) | AH26: =+SUMIF(Рўйхат!$C:$C,$B26,Рўйхат!AI:AI) | AI26: =+SUMIF(Рўйхат!$C:$C,$B26,Рўйхат!AJ:AJ)
A27: =+A26+1 | B27: Самарқанд вилояти ҳокимлиги | C27: =IF(IFERROR(VLOOKUP(B27,Рўйхат!C:E,2,0),"")="[NULL]","",IFERROR(VLOOKUP(B27,Рўйхат!C:E,2,0),"")) | D27: =IFERROR(VLOOKUP(B27,Рўйхат!C:E,3,0),"") | E27: =+SUMIF(Рўйхат!$C:$C,$B27,Рўйхат!G:G) | F27: =+SUMIF(Рўйхат!$C:$C,$B27,Рўйхат!H:H) | G27: =M27 | H27: =R27+W27+AB27+AG27 | I27: =+SUMIF(Рўйхат!$C:$C,$B27,Рўйхат!J:J) | J27: =+SUMIF(Рўйхат!$C:$C,$B27,Рўйхат!K:K) | K27: =+SUMIF(Рўйхат!$C:$C,$B27,Рўйхат!L:L) | L27: =+SUMIF(Рўйхат!$C:$C,$B27,Рўйхат!M:M) | M27: =+SUMIF(Рўйхат!$C:$C,$B27,Рўйхат!N:N) | N27: =+SUMIF(Рўйхат!$C:$C,$B27,Рўйхат!O:O) | O27: =+SUMIF(Рўйхат!$C:$C,$B27,Рўйхат!P:P) | P27: =+SUMIF(Рўйхат!$C:$C,$B27,Рўйхат!Q:Q) | Q27: =+SUMIF(Рўйхат!$C:$C,$B27,Рўйхат!R:R) | R27: =+SUMIF(Рўйхат!$C:$C,$B27,Рўйхат!S:S) | S27: =+SUMIF(Рўйхат!$C:$C,$B27,Рўйхат!T:T) | T27: =+SUMIF(Рўйхат!$C:$C,$B27,Рўйхат!U:U) | U27: =+SUMIF(Рўйхат!$C:$C,$B27,Рўйхат!V:V) | V27: =+SUMIF(Рўйхат!$C:$C,$B27,Рўйхат!W:W) | W27: =+SUMIF(Рўйхат!$C:$C,$B27,Рўйхат!X:X) | X27: =+SUMIF(Рўйхат!$C:$C,$B27,Рўйхат!Y:Y) | Y27: =+SUMIF(Рўйхат!$C:$C,$B27,Рўйхат!Z:Z) | Z27: =+SUMIF(Рўйхат!$C:$C,$B27,Рўйхат!AA:AA) | AA27: =+SUMIF(Рўйхат!$C:$C,$B27,Рўйхат!AB:AB) | AB27: =+SUMIF(Рўйхат!$C:$C,$B27,Рўйхат!AC:AC) | AC27: =+SUMIF(Рўйхат!$C:$C,$B27,Рўйхат!AD:AD) | AD27: =+SUMIF(Рўйхат!$C:$C,$B27,Рўйхат!AE:AE) | AE27: =+SUMIF(Рўйхат!$C:$C,$B27,Рўйхат!AF:AF) | AF27: =+SUMIF(Рўйхат!$C:$C,$B27,Рўйхат!AG:AG) | AG27: =+SUMIF(Рўйхат!$C:$C,$B27,Рўйхат!AH:AH) | AH27: =+SUMIF(Рўйхат!$C:$C,$B27,Рўйхат!AI:AI) | AI27: =+SUMIF(Рўйхат!$C:$C,$B27,Рўйхат!AJ:AJ)
A28: =+A27+1 | B28: Сурхандарё вилояти ҳокимлиги | C28: =IF(IFERROR(VLOOKUP(B28,Рўйхат!C:E,2,0),"")="[NULL]","",IFERROR(VLOOKUP(B28,Рўйхат!C:E,2,0),"")) | D28: =IFERROR(VLOOKUP(B28,Рўйхат!C:E,3,0),"") | E28: =+SUMIF(Рўйхат!$C:$C,$B28,Рўйхат!G:G) | F28: =+SUMIF(Рўйхат!$C:$C,$B28,Рўйхат!H:H) | G28: =M28 | H28: =R28+W28+AB28+AG28 | I28: =+SUMIF(Рўйхат!$C:$C,$B28,Рўйхат!J:J) | J28: =+SUMIF(Рўйхат!$C:$C,$B28,Рўйхат!K:K) | K28: =+SUMIF(Рўйхат!$C:$C,$B28,Рўйхат!L:L) | L28: =+SUMIF(Рўйхат!$C:$C,$B28,Рўйхат!M:M) | M28: =+SUMIF(Рўйхат!$C:$C,$B28,Рўйхат!N:N) | N28: =+SUMIF(Рўйхат!$C:$C,$B28,Рўйхат!O:O) | O28: =+SUMIF(Рўйхат!$C:$C,$B28,Рўйхат!P:P) | P28: =+SUMIF(Рўйхат!$C:$C,$B28,Рўйхат!Q:Q) | Q28: =+SUMIF(Рўйхат!$C:$C,$B28,Рўйхат!R:R) | R28: =+SUMIF(Рўйхат!$C:$C,$B28,Рўйхат!S:S) | S28: =+SUMIF(Рўйхат!$C:$C,$B28,Рўйхат!T:T) | T28: =+SUMIF(Рўйхат!$C:$C,$B28,Рўйхат!U:U) | U28: =+SUMIF(Рўйхат!$C:$C,$B28,Рўйхат!V:V) | V28: =+SUMIF(Рўйхат!$C:$C,$B28,Рўйхат!W:W) | W28: =+SUMIF(Рўйхат!$C:$C,$B28,Рўйхат!X:X) | X28: =+SUMIF(Рўйхат!$C:$C,$B28,Рўйхат!Y:Y) | Y28: =+SUMIF(Рўйхат!$C:$C,$B28,Рўйхат!Z:Z) | Z28: =+SUMIF(Рўйхат!$C:$C,$B28,Рўйхат!AA:AA) | AA28: =+SUMIF(Рўйхат!$C:$C,$B28,Рўйхат!AB:AB) | AB28: =+SUMIF(Рўйхат!$C:$C,$B28,Рўйхат!AC:AC) | AC28: =+SUMIF(Рўйхат!$C:$C,$B28,Рўйхат!AD:AD) | AD28: =+SUMIF(Рўйхат!$C:$C,$B28,Рўйхат!AE:AE) | AE28: =+SUMIF(Рўйхат!$C:$C,$B28,Рўйхат!AF:AF) | AF28: =+SUMIF(Рўйхат!$C:$C,$B28,Рўйхат!AG:AG) | AG28: =+SUMIF(Рўйхат!$C:$C,$B28,Рўйхат!AH:AH) | AH28: =+SUMIF(Рўйхат!$C:$C,$B28,Рўйхат!AI:AI) | AI28: =+SUMIF(Рўйхат!$C:$C,$B28,Рўйхат!AJ:AJ)
A29: =+A28+1 | B29: Хоразм вилояти ҳокимлиги | C29: =IF(IFERROR(VLOOKUP(B29,Рўйхат!C:E,2,0),"")="[NULL]","",IFERROR(VLOOKUP(B29,Рўйхат!C:E,2,0),"")) | D29: =IFERROR(VLOOKUP(B29,Рўйхат!C:E,3,0),"") | E29: =+SUMIF(Рўйхат!$C:$C,$B29,Рўйхат!G:G) | F29: =+SUMIF(Рўйхат!$C:$C,$B29,Рўйхат!H:H) | G29: =M29 | H29: =R29+W29+AB29+AG29 | I29: =+SUMIF(Рўйхат!$C:$C,$B29,Рўйхат!J:J) | J29: =+SUMIF(Рўйхат!$C:$C,$B29,Рўйхат!K:K) | K29: =+SUMIF(Рўйхат!$C:$C,$B29,Рўйхат!L:L) | L29: =+SUMIF(Рўйхат!$C:$C,$B29,Рўйхат!M:M) | M29: =+SUMIF(Рўйхат!$C:$C,$B29,Рўйхат!N:N) | N29: =+SUMIF(Рўйхат!$C:$C,$B29,Рўйхат!O:O) | O29: =+SUMIF(Рўйхат!$C:$C,$B29,Рўйхат!P:P) | P29: =+SUMIF(Рўйхат!$C:$C,$B29,Рўйхат!Q:Q) | Q29: =+SUMIF(Рўйхат!$C:$C,$B29,Рўйхат!R:R) | R29: =+SUMIF(Рўйхат!$C:$C,$B29,Рўйхат!S:S) | S29: =+SUMIF(Рўйхат!$C:$C,$B29,Рўйхат!T:T) | T29: =+SUMIF(Рўйхат!$C:$C,$B29,Рўйхат!U:U) | U29: =+SUMIF(Рўйхат!$C:$C,$B29,Рўйхат!V:V) | V29: =+SUMIF(Рўйхат!$C:$C,$B29,Рўйхат!W:W) | W29: =+SUMIF(Рўйхат!$C:$C,$B29,Рўйхат!X:X) | X29: =+SUMIF(Рўйхат!$C:$C,$B29,Рўйхат!Y:Y) | Y29: =+SUMIF(Рўйхат!$C:$C,$B29,Рўйхат!Z:Z) | Z29: =+SUMIF(Рўйхат!$C:$C,$B29,Рўйхат!AA:AA) | AA29: =+SUMIF(Рўйхат!$C:$C,$B29,Рўйхат!AB:AB) | AB29: =+SUMIF(Рўйхат!$C:$C,$B29,Рўйхат!AC:AC) | AC29: =+SUMIF(Рўйхат!$C:$C,$B29,Рўйхат!AD:AD) | AD29: =+SUMIF(Рўйхат!$C:$C,$B29,Рўйхат!AE:AE) | AE29: =+SUMIF(Рўйхат!$C:$C,$B29,Рўйхат!AF:AF) | AF29: =+SUMIF(Рўйхат!$C:$C,$B29,Рўйхат!AG:AG) | AG29: =+SUMIF(Рўйхат!$C:$C,$B29,Рўйхат!AH:AH) | AH29: =+SUMIF(Рўйхат!$C:$C,$B29,Рўйхат!AI:AI) | AI29: =+SUMIF(Рўйхат!$C:$C,$B29,Рўйхат!AJ:AJ)
